Workbook

Sheet Sheet1
A1: 数据日期 | B1: 港口库存 | C1: 磷酸二铵主流价 | D1: CCPI指数 | E1: 汇率 | F1: 美元指数DXY | G1: WTI原油期货 | H1: 天然气期货 | I1: 黄金期货 | J1: 镇江港颗粒硫磺价格 | L1: 硫磺价格涨跌幅 | M1: 异常事件
A2: 44565 | B2: =VLOOKUP(A2,Sheet2!A:C,2,FALSE) -> 167 | C2: 3480 | D2: =VLOOKUP(A2,Sheet4!A:C,2,FALSE) -> 1100 | E2: =VLOOKUP(A2,Sheet5!A:B,2,FALSE) -> 6.3726 | F2: =VLOOKUP(A2,Sheet6!A:B,2,FALSE) -> 96.26 | G2: =VLOOKUP(A2,WTI原油期货!A:B,2,FALSE) -> 76.74 | H2: =VLOOKUP(A2,天然气期货!A:B,2,FALSE) -> 3.582 | I2: =VLOOKUP(A2,黄金期货!A:B,2,FALSE) -> 1814.6 | J2: =VLOOKUP(A2,Sheet2!A:C,3,FALSE) -> 2480
A3: 44566 | B3: =VLOOKUP(A3,Sheet2!A:C,2,FALSE) -> 166 | C3: 3480 | D3: =VLOOKUP(A3,Sheet4!A:C,2,FALSE) -> 1102 | E3: =VLOOKUP(A3,Sheet5!A:B,2,FALSE) -> 6.3644 | F3: =VLOOKUP(A3,Sheet6!A:B,2,FALSE) -> 96.17 | G3: =VLOOKUP(A3,WTI原油期货!A:B,2,FALSE) -> 77.47 | H3: =VLOOKUP(A3,天然气期货!A:B,2,FALSE) -> 3.71 | I3: =VLOOKUP(A3,黄金期货!A:B,2,FALSE) -> 1825.1 | J3: =VLOOKUP(A3,Sheet2!A:C,3,FALSE) -> 2480 | L3: =(J3-J2)/J2 -> 0
A4: 44567 | B4: =VLOOKUP(A4,Sheet2!A:C,2,FALSE) -> 164 | C4: 3480 | D4: =VLOOKUP(A4,Sheet4!A:C,2,FALSE) -> 1101 | E4: =VLOOKUP(A4,Sheet5!A:B,2,FALSE) -> 6.383 | F4: =VLOOKUP(A4,Sheet6!A:B,2,FALSE) -> 96.32 | G4: =VLOOKUP(A4,WTI原油期货!A:B,2,FALSE) -> 78.88 | H4: =VLOOKUP(A4,天然气期货!A:B,2,FALSE) -> 3.67 | I4: =VLOOKUP(A4,黄金期货!A:B,2,FALSE) -> 1789.2 | J4: =VLOOKUP(A4,Sheet2!A:C,3,FALSE) -> 2480 | L4: =(J4-J3)/J3 -> 0
A5: 44568 | B5: =VLOOKUP(A5,Sheet2!A:C,2,FALSE) -> 162 | C5: 3480 | D5: =VLOOKUP(A5,Sheet4!A:C,2,FALSE) -> 1102 | E5: =VLOOKUP(A5,Sheet5!A:B,2,FALSE) -> 6.3778 | F5: =VLOOKUP(A5,Sheet6!A:B,2,FALSE) -> 95.72 | G5: =VLOOKUP(A5,WTI原油期货!A:B,2,FALSE) -> 78.44 | H5: =VLOOKUP(A5,天然气期货!A:B,2,FALSE) -> 3.726 | I5: =VLOOKUP(A5,黄金期货!A:B,2,FALSE) -> 1797.4 | J5: =VLOOKUP(A5,Sheet2!A:C,3,FALSE) -> 2480 | L5: =(J5-J4)/J4 -> 0
A6: 44571 | B6: =VLOOKUP(A6,Sheet2!A:C,2,FALSE) -> 155 | C6: 3480 | D6: =VLOOKUP(A6,Sheet4!A:C,2,FALSE) -> 1104 | E6: =VLOOKUP(A6,Sheet5!A:B,2,FALSE) -> 6.3762 | F6: =VLOOKUP(A6,Sheet6!A:B,2,FALSE) -> 95.99 | G6: =VLOOKUP(A6,WTI原油期货!A:B,2,FALSE) -> 77.7 | H6: =VLOOKUP(A6,天然气期货!A:B,2,FALSE) -> 3.834 | I6: =VLOOKUP(A6,黄金期货!A:B,2,FALSE) -> 1798.8 | J6: =VLOOKUP(A6,Sheet2!A:C,3,FALSE) -> 2470 | L6: =(J6-J5)/J5 -> -0.0040322581
A7: 44572 | B7: =VLOOKUP(A7,Sheet2!A:C,2,FALSE) -> 154 | C7: 3480 | D7: =VLOOKUP(A7,Sheet4!A:C,2,FALSE) -> 1108 | E7: =VLOOKUP(A7,Sheet5!A:B,2,FALSE) -> 6.3741 | F7: =VLOOKUP(A7,Sheet6!A:B,2,FALSE) -> 95.62 | G7: =VLOOKUP(A7,WTI原油期货!A:B,2,FALSE) -> 80.67 | H7: =VLOOKUP(A7,天然气期货!A:B,2,FALSE) -> 3.968 | I7: =VLOOKUP(A7,黄金期货!A:B,2,FALSE) -> 1818.5 | J7: =VLOOKUP(A7,Sheet2!A:C,3,FALSE) -> 2440 | L7: =(J7-J6)/J6 -> -0.012145749
A8: 44573 | B8: =VLOOKUP(A8,Sheet2!A:C,2,FALSE) -> 153 | C8: 3480 | D8: =VLOOKUP(A8,Sheet4!A:C,2,FALSE) -> 1110 | E8: =VLOOKUP(A8,Sheet5!A:B,2,FALSE) -> 6.3584 | F8: =VLOOKUP(A8,Sheet6!A:B,2,FALSE) -> 94.92 | G8: =VLOOKUP(A8,WTI原油期货!A:B,2,FALSE) -> 82.02 | H8: =VLOOKUP(A8,天然气期货!A:B,2,FALSE) -> 4.327 | I8: =VLOOKUP(A8,黄金期货!A:B,2,FALSE) -> 1827.3 | J8: =VLOOKUP(A8,Sheet2!A:C,3,FALSE) -> 2420 | L8: =(J8-J7)/J7 -> -0.0081967213
A9: 44574 | B9: =VLOOKUP(A9,Sheet2!A:C,2,FALSE) -> 151 | C9: 3480 | D9: =VLOOKUP(A9,Sheet4!A:C,2,FALSE) -> 1112 | E9: =VLOOKUP(A9,Sheet5!A:B,2,FALSE) -> 6.3599 | F9: =VLOOKUP(A9,Sheet6!A:B,2,FALSE) -> 94.79 | G9: =VLOOKUP(A9,WTI原油期货!A:B,2,FALSE) -> 81.62 | H9: =VLOOKUP(A9,天然气期货!A:B,2,FALSE) -> 4.005 | I9: =VLOOKUP(A9,黄金期货!A:B,2,FALSE) -> 1821.4 | J9: =VLOOKUP(A9,Sheet2!A:C,3,FALSE) -> 2440 | L9: =(J9-J8)/J8 -> 0.0082644628
A10: 44575 | B10: =VLOOKUP(A10,Sheet2!A:C,2,FALSE) -> 149 | C10: 3480 | D10: =VLOOKUP(A10,Sheet4!A:C,2,FALSE) -> 1112 | E10: =VLOOKUP(A10,Sheet5!A:B,2,FALSE) -> 6.3528 | F10: =VLOOKUP(A10,Sheet6!A:B,2,FALSE) -> 95.17 | G10: =VLOOKUP(A10,WTI原油期货!A:B,2,FALSE) -> 83.3 | H10: =VLOOKUP(A10,天然气期货!A:B,2,FALSE) -> 4.081 | I10: =VLOOKUP(A10,黄金期货!A:B,2,FALSE) -> 1816.5 | J10: =VLOOKUP(A10,Sheet2!A:C,3,FALSE) -> 2440 | L10: =(J10-J9)/J9 -> 0
A11: 44578 | B11: =VLOOKUP(A11,Sheet2!A:C,2,FALSE) -> 149 | C11: 3480 | D11: =VLOOKUP(A11,Sheet4!A:C,2,FALSE) -> 1112 | E11: =VLOOKUP(A11,Sheet5!A:B,2,FALSE) -> 6.3488 | F11: =VLOOKUP(A11,Sheet6!A:B,2,FALSE) -> 95.26 | G11: =VLOOKUP(A11,WTI原油期货!A:B,2,FALSE) -> 83.69 | H11: =VLOOKUP(A11,天然气期货!A:B,2,FALSE) -> 4.276 | I11: =VLOOKUP(A11,黄金期货!A:B,2,FALSE) -> 1812.4 | J11: =VLOOKUP(A11,Sheet2!A:C,3,FALSE) -> 2440 | L11: =(J11-J10)/J10 -> 0
A12: 44579 | B12: =VLOOKUP(A12,Sheet2!A:C,2,FALSE) -> 147 | C12: 3480 | D12: =VLOOKUP(A12,Sheet4!A:C,2,FALSE) -> 1116 | E12: =VLOOKUP(A12,Sheet5!A:B,2,FALSE) -> 6.353 | F12: =VLOOKUP(A12,Sheet6!A:B,2,FALSE) -> 95.73 | G12: =VLOOKUP(A12,WTI原油期货!A:B,2,FALSE) -> 84.83 | H12: =VLOOKUP(A12,天然气期货!A:B,2,FALSE) -> 4.048 | I12: =VLOOKUP(A12,黄金期货!A:B,2,FALSE) -> 1812.4 | J12: =VLOOKUP(A12,Sheet2!A:C,3,FALSE) -> 2465 | L12: =(J12-J11)/J11 -> 0.010245902
A13: 44580 | B13: =VLOOKUP(A13,Sheet2!A:C,2,FALSE) -> 147 | C13: 3480 | D13: =VLOOKUP(A13,Sheet4!A:C,2,FALSE) -> 1118 | E13: =VLOOKUP(A13,Sheet5!A:B,2,FALSE) -> 6.345 | F13: =VLOOKUP(A13,Sheet6!A:B,2,FALSE) -> 95.51 | G13: =VLOOKUP(A13,WTI原油期货!A:B,2,FALSE) -> 85.8 | H13: =VLOOKUP(A13,天然气期货!A:B,2,FALSE) -> 3.845 | I13: =VLOOKUP(A13,黄金期货!A:B,2,FALSE) -> 1843.2 | J13: =VLOOKUP(A13,Sheet2!A:C,3,FALSE) -> 2470 | L13: =(J13-J12)/J12 -> 0.0020283976
A14: 44581 | B14: =VLOOKUP(A14,Sheet2!A:C,2,FALSE) -> 147 | C14: 3480 | D14: =VLOOKUP(A14,Sheet4!A:C,2,FALSE) -> 1122 | E14: =VLOOKUP(A14,Sheet5!A:B,2,FALSE) -> 6.3411 | F14: =VLOOKUP(A14,Sheet6!A:B,2,FALSE) -> 95.74 | G14: =VLOOKUP(A14,WTI原油期货!A:B,2,FALSE) -> 85.55 | H14: =VLOOKUP(A14,天然气期货!A:B,2,FALSE) -> 3.649 | I14: =VLOOKUP(A14,黄金期货!A:B,2,FALSE) -> 1842.6 | J14: =VLOOKUP(A14,Sheet2!A:C,3,FALSE) -> 2470 | L14: =(J14-J13)/J13 -> 0
... A20: 44589 | B20: =VLOOKUP(A20,Sheet2!A:C,2,FALSE) -> 151 | C20: 3480 | D20: =VLOOKUP(A20,Sheet4!A:C,2,FALSE) -> 1130 | E20: =VLOOKUP(A20,Sheet5!A:B,2,FALSE) -> 6.361 | F20: =VLOOKUP(A20,Sheet6!A:B,2,FALSE) -> 97.27 | G20: =VLOOKUP(A20,WTI原油期货!A:B,2,FALSE) -> 85.43 | H20: =VLOOKUP(A20,天然气期货!A:B,2,FALSE) -> 4.473 | I20: =VLOOKUP(A20,黄金期货!A:B,2,FALSE) -> 1785.8 | J20: =VLOOKUP(A20,Sheet2!A:C,3,FALSE) -> 2460 | L20: =(J20-J19)/J19 -> 0
A21: 44590 | B21: =VLOOKUP(A21,Sheet2!A:C,2,FALSE) -> 151 | C21: 3480 | D21: =VLOOKUP(A21,Sheet4!A:C,2,FALSE) -> 1130 | E21: =E20 -> 6.361 | F21: =F20 -> 97.27 | G21: =G20 -> 85.43 | H21: =H20 -> 4.473 | I21: =I20 -> 1785.8 | J21: =VLOOKUP(A21,Sheet2!A:C,3,FALSE) -> 2460 | L21: =(J21-J20)/J20 -> 0
A22: 44591 | B22: =VLOOKUP(A22,Sheet2!A:C,2,FALSE) -> 150 | C22: 3480 | D22: =VLOOKUP(A22,Sheet4!A:C,2,FALSE) -> 1130 | E22: =E21 -> 6.361 | F22: =F21 -> 97.27 | G22: =G21 -> 85.43 | H22: =H21 -> 4.473 | I22: =I21 -> 1785.8 | J22: =VLOOKUP(A22,Sheet2!A:C,3,FALSE) -> 2460 | L22: =(J22-J21)/J21 -> 0
A23: 44599 | B23: =VLOOKUP(A23,Sheet2!A:C,2,FALSE) -> 144 | C23: 3480 | D23: =VLOOKUP(A23,Sheet4!A:C,2,FALSE) -> 1141 | E23: =VLOOKUP(A23,Sheet5!A:B,2,FALSE) -> 6.3623 | F23: =VLOOKUP(A23,Sheet6!A:B,2,FALSE) -> 95.4 | G23: =VLOOKUP(A23,WTI原油期货!A:B,2,FALSE) -> 89.77 | H23: =VLOOKUP(A23,天然气期货!A:B,2,FALSE) -> 4.198 | I23: =VLOOKUP(A23,黄金期货!A:B,2,FALSE) -> 1820.8 | J23: =VLOOKUP(A23,Sheet2!A:C,3,FALSE) -> 2470 | L23: =(J23-J22)/J22 -> 0.0040650407
A24: 44600 | B24: =VLOOKUP(A24,Sheet2!A:C,2,FALSE) -> 144 | C24: 3480 | D24: =VLOOKUP(A24,Sheet4!A:C,2,FALSE) -> 1150 | E24: =VLOOKUP(A24,Sheet5!A:B,2,FALSE) -> 6.3666 | F24: =VLOOKUP(A24,Sheet6!A:B,2,FALSE) -> 95.64 | G24: =VLOOKUP(A24,WTI原油期货!A:B,2,FALSE) -> 87.9 | H24: =VLOOKUP(A24,天然气期货!A:B,2,FALSE) -> 4.218 | I24: =VLOOKUP(A24,黄金期货!A:B,2,FALSE) -> 1826.8 | J24: =VLOOKUP(A24,Sheet2!A:C,3,FALSE) -> 2470 | L24: =(J24-J23)/J23 -> 0
A25: 44601 | B25: =VLOOKUP(A25,Sheet2!A:C,2,FALSE) -> 146 | C25: 3480 | D25: =VLOOKUP(A25,Sheet4!A:C,2,FALSE) -> 1152 | E25: =VLOOKUP(A25,Sheet5!A:B,2,FALSE) -> 6.3627 | F25: =VLOOKUP(A25,Sheet6!A:B,2,FALSE) -> 95.49 | G25: =VLOOKUP(A25,WTI原油期货!A:B,2,FALSE) -> 88.53 | H25: =VLOOKUP(A25,天然气期货!A:B,2,FALSE) -> 3.98 | I25: =VLOOKUP(A25,黄金期货!A:B,2,FALSE) -> 1835.6 | J25: =VLOOKUP(A25,Sheet2!A:C,3,FALSE) -> 2470 | L25: =(J25-J24)/J24 -> 0
A26: 44602 | B26: =VLOOKUP(A26,Sheet2!A:C,2,FALSE) -> 147 | C26: 3480 | D26: =VLOOKUP(A26,Sheet4!A:C,2,FALSE) -> 1156 | E26: =VLOOKUP(A26,Sheet5!A:B,2,FALSE) -> 6.3541 | F26: =VLOOKUP(A26,Sheet6!A:B,2,FALSE) -> 95.55 | G26: =VLOOKUP(A26,WTI原油期货!A:B,2,FALSE) -> 88.56 | H26: =VLOOKUP(A26,天然气期货!A:B,2,FALSE) -> 3.943 | I26: =VLOOKUP(A26,黄金期货!A:B,2,FALSE) -> 1836.4 | J26: =VLOOKUP(A26,Sheet2!A:C,3,FALSE) -> 2480 | L26: =(J26-J25)/J25 -> 0.004048583
A27: 44603 | B27: =VLOOKUP(A27,Sheet2!A:C,2,FALSE) -> 145 | C27: 3480 | D27: =VLOOKUP(A27,Sheet4!A:C,2,FALSE) -> 1157 | E27: =VLOOKUP(A27,Sheet5!A:B,2,FALSE) -> 6.3546 | F27: =VLOOKUP(A27,Sheet6!A:B,2,FALSE) -> 96.08 | G27: =VLOOKUP(A27,WTI原油期货!A:B,2,FALSE) -> 91.42 | H27: =VLOOKUP(A27,天然气期货!A:B,2,FALSE) -> 3.935 | I27: =VLOOKUP(A27,黄金期货!A:B,2,FALSE) -> 1841.1 | J27: =VLOOKUP(A27,Sheet2!A:C,3,FALSE) -> 2490 | L27: =(J27-J26)/J26 -> 0.0040322581
A28: 44606 | B28: =VLOOKUP(A28,Sheet2!A:C,2,FALSE) -> 138 | C28: 3500 | D28: =VLOOKUP(A28,Sheet4!A:C,2,FALSE) -> 1161 | E28: =VLOOKUP(A28,Sheet5!A:B,2,FALSE) -> 6.3576 | F28: =VLOOKUP(A28,Sheet6!A:B,2,FALSE) -> 96.37 | G28: =VLOOKUP(A28,WTI原油期货!A:B,2,FALSE) -> 93.5 | H28: =VLOOKUP(A28,天然气期货!A:B,2,FALSE) -> 4.16 | I28: =VLOOKUP(A28,黄金期货!A:B,2,FALSE) -> 1868.3 | J28: =VLOOKUP(A28,Sheet2!A:C,3,FALSE) -> 2490 | L28: =(J28-J27)/J27 -> 0
A29: 44607 | B29: =VLOOKUP(A29,Sheet2!A:C,2,FALSE) -> 135 | C29: 3500 | D29: =VLOOKUP(A29,Sheet4!A:C,2,FALSE) -> 1161 | E29: =VLOOKUP(A29,Sheet5!A:B,2,FALSE) -> 6.3392 | F29: =VLOOKUP(A29,Sheet6!A:B,2,FALSE) -> 95.99 | G29: =VLOOKUP(A29,WTI原油期货!A:B,2,FALSE) -> 90.21 | H29: =VLOOKUP(A29,天然气期货!A:B,2,FALSE) -> 4.241 | I29: =VLOOKUP(A29,黄金期货!A:B,2,FALSE) -> 1855.1 | J29: =VLOOKUP(A29,Sheet2!A:C,3,FALSE) -> 2490 | L29: =(J29-J28)/J28 -> 0
A30: 44608 | B30: =VLOOKUP(A30,Sheet2!A:C,2,FALSE) -> 134 | C30: 3500 | D30: =VLOOKUP(A30,Sheet4!A:C,2,FALSE) -> 1159 | E30: =VLOOKUP(A30,Sheet5!A:B,2,FALSE) -> 6.3372 | F30: =VLOOKUP(A30,Sheet6!A:B,2,FALSE) -> 95.7 | G30: =VLOOKUP(A30,WTI原油期货!A:B,2,FALSE) -> 91.83 | H30: =VLOOKUP(A30,天然气期货!A:B,2,FALSE) -> 4.572 | I30: =VLOOKUP(A30,黄金期货!A:B,2,FALSE) -> 1870.5 | J30: =VLOOKUP(A30,Sheet2!A:C,3,FALSE) -> 2490 | L30: =(J30-J29)/J29 -> 0
A31: 44609 | B31: =VLOOKUP(A31,Sheet2!A:C,2,FALSE) -> 133 | C31: 3500 | D31: =VLOOKUP(A31,Sheet4!A:C,2,FALSE) -> 1158 | E31: =VLOOKUP(A31,Sheet5!A:B,2,FALSE) -> 6.3384 | F31: =VLOOKUP(A31,Sheet6!A:B,2,FALSE) -> 95.8 | G31: =VLOOKUP(A31,WTI原油期货!A:B,2,FALSE) -> 90.04 | H31: =VLOOKUP(A31,天然气期货!A:B,2,FALSE) -> 4.43 | I31: =VLOOKUP(A31,黄金期货!A:B,2,FALSE) -> 1901 | J31: =VLOOKUP(A31,Sheet2!A:C,3,FALSE) -> 2490 | L31: =(J31-J30)/J30 -> 0
A32: 44610 | B32: =VLOOKUP(A32,Sheet2!A:C,2,FALSE) -> 142 | C32: 3500 | D32: =VLOOKUP(A32,Sheet4!A:C,2,FALSE) -> 1156 | E32: =VLOOKUP(A32,Sheet5!A:B,2,FALSE) -> 6.3256 | F32: =VLOOKUP(A32,Sheet6!A:B,2,FALSE) -> 96.04 | G32: =VLOOKUP(A32,WTI原油期货!A:B,2,FALSE) -> 90.21 | H32: =VLOOKUP(A32,天然气期货!A:B,2,FALSE) -> 4.377 | I32: =VLOOKUP(A32,黄金期货!A:B,2,FALSE) -> 1898.8 | J32: =VLOOKUP(A32,Sheet2!A:C,3,FALSE) -> 2530 | L32: =(J32-J31)/J31 -> 0.016064257
A33: 44613 | B33: =VLOOKUP(A33,Sheet2!A:C,2,FALSE) -> 134 | C33: 3500 | D33: =VLOOKUP(A33,Sheet4!A:C,2,FALSE) -> 1155 | E33: =VLOOKUP(A33,Sheet5!A:B,2,FALSE) -> 6.3353 | F33: =VLOOKUP(A33,Sheet6!A:B,2,FALSE) -> 96.08 | G33: =VLOOKUP(A33,WTI原油期货!A:B,2,FALSE) -> 92.65 | H33: =VLOOKUP(A33,天然气期货!A:B,2,FALSE) -> 4.705 | I33: =VLOOKUP(A33,黄金期货!A:B,2,FALSE) -> 1907.4 | J33: =VLOOKUP(A33,Sheet2!A:C,3,FALSE) -> 2550 | L33: =(J33-J32)/J32 -> 0.0079051383
A34: 44614 | B34: =VLOOKUP(A34,Sheet2!A:C,2,FALSE) -> 132 | C34: 3530 | D34: =VLOOKUP(A34,Sheet4!A:C,2,FALSE) -> 1160 | E34: =VLOOKUP(A34,Sheet5!A:B,2,FALSE) -> 6.3265 | F34: =VLOOKUP(A34,Sheet6!A:B,2,FALSE) -> 96.03 | G34: =VLOOKUP(A34,WTI原油期货!A:B,2,FALSE) -> 91.91 | H34: =VLOOKUP(A34,天然气期货!A:B,2,FALSE) -> 4.461 | I34: =VLOOKUP(A34,黄金期货!A:B,2,FALSE) -> 1906.4 | J34: =VLOOKUP(A34,Sheet2!A:C,3,FALSE) -> 2570 | L34: =(J34-J33)/J33 -> 0.0078431373
... A62: 44652 | B62: =VLOOKUP(A62,Sheet2!A:C,2,FALSE) -> 125 | C62: 3580 | D62: =VLOOKUP(A62,Sheet4!A:C,2,FALSE) -> 1212 | E62: =VLOOKUP(A62,Sheet5!A:B,2,FALSE) -> 6.3631 | F62: =VLOOKUP(A62,Sheet6!A:B,2,FALSE) -> 98.63 | G62: =VLOOKUP(A62,WTI原油期货!A:B,2,FALSE) -> 97.9 | H62: =VLOOKUP(A62,天然气期货!A:B,2,FALSE) -> 5.795 | I62: =VLOOKUP(A62,黄金期货!A:B,2,FALSE) -> 1920.9 | J62: =VLOOKUP(A62,Sheet2!A:C,3,FALSE) -> 3400 | L62: =(J62-J61)/J61 -> 0
A63: 44653 | B63: =VLOOKUP(A63,Sheet2!A:C,2,FALSE) -> 125 | C63: 3580 | D63: =VLOOKUP(A63,Sheet4!A:C,2,FALSE) -> 1212 | E63: =E62 -> 6.3631 | F63: =F62 -> 98.63 | G63: =G62 -> 97.9 | H63: =H62 -> 5.795 | I63: =I62 -> 1920.9 | J63: =VLOOKUP(A63,Sheet2!A:C,3,FALSE) -> 3400 | L63: =(J63-J62)/J62 -> 0
A64: 44657 | B64: =VLOOKUP(A64,Sheet2!A:C,2,FALSE) -> 123 | C64: 3580 | D64: =VLOOKUP(A64,Sheet4!A:C,2,FALSE) -> 1214 | E64: =VLOOKUP(A64,Sheet5!A:B,2,FALSE) -> 6.3599 | F64: =VLOOKUP(A64,Sheet6!A:B,2,FALSE) -> 99.6 | G64: =VLOOKUP(A64,WTI原油期货!A:B,2,FALSE) -> 95.41 | H64: =VLOOKUP(A64,天然气期货!A:B,2,FALSE) -> 6.107 | I64: =VLOOKUP(A64,黄金期货!A:B,2,FALSE) -> 1919.7 | J64: =VLOOKUP(A64,Sheet2!A:C,3,FALSE) -> 3390 | L64: =(J64-J63)/J63 -> -0.0029411765
A65: 44658 | B65: =VLOOKUP(A65,Sheet2!A:C,2,FALSE) -> 125 | C65: 3580 | D65: =VLOOKUP(A65,Sheet4!A:C,2,FALSE) -> 1213 | E65: =VLOOKUP(A65,Sheet5!A:B,2,FALSE) -> 6.3604 | F65: =VLOOKUP(A65,Sheet6!A:B,2,FALSE) -> 99.75 | G65: =VLOOKUP(A65,WTI原油期货!A:B,2,FALSE) -> 95.51 | H65: =VLOOKUP(A65,天然气期货!A:B,2,FALSE) -> 6.436 | I65: =VLOOKUP(A65,黄金期货!A:B,2,FALSE) -> 1934.7 | J65: =VLOOKUP(A65,Sheet2!A:C,3,FALSE) -> 3390 | L65: =(J65-J64)/J64 -> 0
A66: 44659 | B66: =VLOOKUP(A66,Sheet2!A:C,2,FALSE) -> 125 | C66: 3580 | D66: =VLOOKUP(A66,Sheet4!A:C,2,FALSE) -> 1210 | E66: =VLOOKUP(A66,Sheet5!A:B,2,FALSE) -> 6.365 | F66: =VLOOKUP(A66,Sheet6!A:B,2,FALSE) -> 99.8 | G66: =VLOOKUP(A66,WTI原油期货!A:B,2,FALSE) -> 97.73 | H66: =VLOOKUP(A66,天然气期货!A:B,2,FALSE) -> 6.356 | I66: =VLOOKUP(A66,黄金期货!A:B,2,FALSE) -> 1942.4 | J66: =VLOOKUP(A66,Sheet2!A:C,3,FALSE) -> 3390 | L66: =(J66-J65)/J65 -> 0
A67: 44662 | B67: =VLOOKUP(A67,Sheet2!A:C,2,FALSE) -> 128 | C67: 3580 | D67: =VLOOKUP(A67,Sheet4!A:C,2,FALSE) -> 1208 | E67: =VLOOKUP(A67,Sheet5!A:B,2,FALSE) -> 6.37 | F67: =VLOOKUP(A67,Sheet6!A:B,2,FALSE) -> 99.93 | G67: =VLOOKUP(A67,WTI原油期货!A:B,2,FALSE) -> 93.92 | H67: =VLOOKUP(A67,天然气期货!A:B,2,FALSE) -> 6.723 | I67: =VLOOKUP(A67,黄金期货!A:B,2,FALSE) -> 1945.1 | J67: =VLOOKUP(A67,Sheet2!A:C,3,FALSE) -> 3390 | L67: =(J67-J66)/J66 -> 0
A68: 44663 | B68: =VLOOKUP(A68,Sheet2!A:C,2,FALSE) -> 128 | C68: 3580 | D68: =VLOOKUP(A68,Sheet4!A:C,2,FALSE) -> 1206 | E68: =VLOOKUP(A68,Sheet5!A:B,2,FALSE) -> 6.366 | F68: =VLOOKUP(A68,Sheet6!A:B,2,FALSE) -> 100.29 | G68: =VLOOKUP(A68,WTI原油期货!A:B,2,FALSE) -> 100.15 | H68: =VLOOKUP(A68,天然气期货!A:B,2,FALSE) -> 6.763 | I68: =VLOOKUP(A68,黄金期货!A:B,2,FALSE) -> 1973.2 | J68: =VLOOKUP(A68,Sheet2!A:C,3,FALSE) -> 3390 | L68: =(J68-J67)/J67 -> 0
A69: 44664 | B69: =VLOOKUP(A69,Sheet2!A:C,2,FALSE) -> 128 | C69: 3580 | D69: =VLOOKUP(A69,Sheet4!A:C,2,FALSE) -> 1207 | E69: =VLOOKUP(A69,Sheet5!A:B,2,FALSE) -> 6.3682 | F69: =VLOOKUP(A69,Sheet6!A:B,2,FALSE) -> 99.88 | G69: =VLOOKUP(A69,WTI原油期货!A:B,2,FALSE) -> 103.79 | H69: =VLOOKUP(A69,天然气期货!A:B,2,FALSE) -> 7.096 | I69: =VLOOKUP(A69,黄金期货!A:B,2,FALSE) -> 1981.9 | J69: =VLOOKUP(A69,Sheet2!A:C,3,FALSE) -> 3340 | L69: =(J69-J68)/J68 -> -0.014749263
A70: 44665 | B70: =VLOOKUP(A70,Sheet2!A:C,2,FALSE) -> 125 | C70: 3580 | D70: =VLOOKUP(A70,Sheet4!A:C,2,FALSE) -> 1207 | E70: =VLOOKUP(A70,Sheet5!A:B,2,FALSE) -> 6.3784 | F70: =VLOOKUP(A70,Sheet6!A:B,2,FALSE) -> 100.32 | G70: =VLOOKUP(A70,WTI原油期货!A:B,2,FALSE) -> 106.38 | H70: =VLOOKUP(A70,天然气期货!A:B,2,FALSE) -> 7.423 | I70: =VLOOKUP(A70,黄金期货!A:B,2,FALSE) -> 1972.2 | J70: =VLOOKUP(A70,Sheet2!A:C,3,FALSE) -> 3460 | L70: =(J70-J69)/J69 -> 0.035928144
A71: 44666 | B71: =VLOOKUP(A71,Sheet2!A:C,2,FALSE) -> 122 | C71: 3580 | D71: =VLOOKUP(A71,Sheet4!A:C,2,FALSE) -> 1209 | E71: =VLOOKUP(A71,Sheet5!A:B,2,FALSE) -> 6.3712 | F71: =VLOOKUP(A71,Sheet6!A:B,2,FALSE) -> 100.32 | G71: =G70 -> 106.38 | H71: =H70 -> 7.423 | I71: =I70 -> 1972.2 | J71: =VLOOKUP(A71,Sheet2!A:C,3,FALSE) -> 3460 | L71: =(J71-J70)/J70 -> 0
A72: 44669 | B72: =VLOOKUP(A72,Sheet2!A:C,2,FALSE) -> 121 | C72: 3580 | D72: =VLOOKUP(A72,Sheet4!A:C,2,FALSE) -> 1209 | E72: =VLOOKUP(A72,Sheet5!A:B,2,FALSE) -> 6.367 | F72: =VLOOKUP(A72,Sheet6!A:B,2,FALSE) -> 100.78 | G72: =VLOOKUP(A72,WTI原油期货!A:B,2,FALSE) -> 107.61 | H72: =VLOOKUP(A72,天然气期货!A:B,2,FALSE) -> 7.958 | I72: =VLOOKUP(A72,黄金期货!A:B,2,FALSE) -> 1983.6 | J72: =VLOOKUP(A72,Sheet2!A:C,3,FALSE) -> 3460 | L72: =(J72-J71)/J71 -> 0
...

Sheet Sheet2
A1: 日期 | B1: 港口库存 | C1: 镇江港颗粒硫磺价格
A2: 41641 | B2: 116.9 | C2: 1250
A3: 41642 | B3: 114.6 | C3: 1250
A4: 41642 | B4: 114.6 | C4: 1250
A5: 41645 | B5: 111 | C5: 1375
A6: 41646 | B6: 108.7 | C6: 1375
A7: 41647 | B7: 106 | C7: 1375
A8: 41648 | B8: 106 | C8: 1375
A9: 41649 | B9: 106 | C9: 1342.5
A10: 41652 | B10: 106 | C10: 1342.5
A11: 41653 | B11: 109 | C11: 1342.5
A12: 41654 | B12: 111.6 | C12: 1300
A13: 41655 | B13: 113.6 | C13: 1311.25
... A1885: 45622 | B1885: 216.7 | C1885: 1580

Sheet Sheet3
A1: 数据日期 | B1: 产品名称 | C1: 最低价 | D1: 最高价 | E1: 主流价 | F1: 单位
A2: 45908 | B2: 硫磺 | C2: 2600 | D2: 2620 | E2: 2610 | F2: 元/吨
A3: 45905 | B3: 硫磺 | C3: 2600 | D3: 2620 | E3: 2610 | F3: 元/吨
A4: 45904 | B4: 硫磺 | C4: 2580 | D4: 2600 | E4: 2590 | F4: 元/吨
A5: 45903 | B5: 硫磺 | C5: 2595 | D5: 2615 | E5: 2605 | F5: 元/吨
A6: 45902 | B6: 硫磺 | C6: 2605 | D6: 2625 | E6: 2615 | F6: 元/吨
A7: 45901 | B7: 硫磺 | C7: 2615 | D7: 2635 | E7: 2625 | F7: 元/吨
A8: 45898 | B8: 硫磺 | C8: 2610 | D8: 2630 | E8: 2620 | F8: 元/吨
A9: 45897 | B9: 硫磺 | C9: 2580 | D9: 2600 | E9: 2590 | F9: 元/吨
A10: 45896 | B10: 硫磺 | C10: 2580 | D10: 2600 | E10: 2590 | F10: 元/吨
A11: 45895 | B11: 硫磺 | C11: 2600 | D11: 2620 | E11: 2610 | F11: 元/吨
A12: 45894 | B12: 硫磺 | C12: 2585 | D12: 2605 | E12: 2595 | F12: 元/吨
A13: 45891 | B13: 硫磺 | C13: 2570 | D13: 2590 | E13: 2580 | F13: 元/吨
... A276: 45505 | B276: 硫磺 | C276: 1190 | D276: 1210 | E276: 1200 | F276: 元/吨

Sheet Sheet4
A1: 44561 | B1: 1101 | C1: 0
A2: 44562 | B2: 1101 | C2: 0
A3: 44563 | B3: 1101 | C3: 0
A4: 44564 | B4: 1101 | C4: 0
A5: 44565 | B5: 1100 | C5: -0.0009
A6: 44566 | B6: 1102 | C6: 0.0018
A7: 44567 | B7: 1101 | C7: -0.0009
A8: 44568 | B8: 1102 | C8: 0.0009
A9: 44569 | B9: 1102 | C9: 0
A10: 44570 | B10: 1102 | C10: 0
A11: 44571 | B11: 1104 | C11: 0.0018
A12: 44572 | B12: 1108 | C12: 0.0036
... A1346: 45910 | B1346: 867 | C1346: -0.0012

Sheet Sheet5
A1: 日期 | B1: 收盘 | C1: 开盘 | D1: 高 | E1: 低 | F1: 交易量 | G1: 涨跌幅
A2: 45911 | B2: 7.1202 | C2: 7.1172 | D2: 7.1259 | E2: 7.1186 | G2: -0.0001
A3: 45910 | B3: 7.1212 | C3: 7.1306 | D3: 7.1306 | E3: 7.1191 | G3: 0
A4: 45909 | B4: 7.1215 | C4: 7.1299 | D4: 7.1299 | E4: 7.1214 | G4: -0.0012
A5: 45908 | B5: 7.1299 | C5: 7.1318 | D5: 7.1367 | E5: 7.1293 | G5: -0.0004
A6: 45905 | B6: 7.1329 | C6: 7.1383 | D6: 7.1396 | E6: 7.1326 | G6: -0.0012
A7: 45904 | B7: 7.1417 | C7: 7.1415 | D7: 7.1439 | E7: 7.1384 | G7: -0.0001
A8: 45903 | B8: 7.1422 | C8: 7.1386 | D8: 7.1489 | E8: 7.1375 | G8: 0.0004
A9: 45902 | B9: 7.1395 | C9: 7.1387 | D9: 7.15 | E9: 7.1375 | G9: 0.0002
A10: 45901 | B10: 7.1378 | C10: 7.1312 | D10: 7.1382 | E10: 7.1282 | G10: 0.001
A11: 45898 | B11: 7.1308 | C11: 7.1342 | D11: 7.1345 | E11: 7.1265 | G11: 0
A12: 45897 | B12: 7.1307 | C12: 7.1485 | D12: 7.1551 | E12: 7.1301 | G12: -0.0033
A13: 45896 | B13: 7.1543 | C13: 7.1508 | D13: 7.1631 | E13: 7.1454 | G13: 0.0002
... A962: 44567 | B962: 6.383 | C962: 6.3707 | D962: 6.3859 | E962: 6.3667 | G962: 0.0029
A963: 44566 | B963: 6.3644 | C963: 6.3724 | D963: 6.3745 | E963: 6.3623 | F963: 4.51K | G963: -0.0013
A964: 44565 | B964: 6.3726 | C964: 6.3719 | D964: 6.3795 | E964: 6.3691 | F964: 4.65K | G964: 0.0026
A965: 44564 | B965: 6.3561 | C965: 6.3561 | D965: 6.3561 | E965: 6.3561 | G965: 0

Sheet Sheet6
A1: 日期 | B1: 收盘 | C1: 开盘 | D1: 高 | E1: 低 | F1: 交易量 | G1: 涨跌幅
A2: 44564 | B2: 96.21 | C2: 95.67 | D2: 96.33 | E2: 95.63 | G2: 0.0026
A3: 44565 | B3: 96.26 | C3: 96.19 | D3: 96.46 | E3: 96.03 | G3: 0.0005
A4: 44566 | B4: 96.17 | C4: 96.31 | D4: 96.33 | E4: 95.89 | G4: -0.0009
A5: 44567 | B5: 96.32 | C5: 96.2 | D5: 96.39 | E5: 96.04 | G5: 0.0015
A6: 44568 | B6: 95.72 | C6: 96.26 | D6: 96.29 | E6: 95.71 | G6: -0.0062
A7: 44571 | B7: 95.99 | C7: 95.74 | D7: 96.23 | E7: 95.74 | G7: 0.0028
A8: 44572 | B8: 95.62 | C8: 95.93 | D8: 96.07 | E8: 95.58 | G8: -0.0038
A9: 44573 | B9: 94.92 | C9: 95.58 | D9: 95.69 | E9: 94.91 | G9: -0.0074
A10: 44574 | B10: 94.79 | C10: 94.99 | D10: 95.02 | E10: 94.66 | G10: -0.0013
A11: 44575 | B11: 95.17 | C11: 94.87 | D11: 95.27 | E11: 94.63 | G11: 0.004
A12: 44578 | B12: 95.26 | C12: 95.17 | D12: 95.35 | E12: 95.04 | G12: 0.001
A13: 44579 | B13: 95.73 | C13: 95.22 | D13: 95.83 | E13: 95.13 | G13: 0.005
... A865: 45782 | B865: 99.83 | C865: 100 | D865: 100.05 | E865: 99.46 | G865: -0.002
A866: 45783 | B866: 99.24 | C866: 99.83 | D866: 100.1 | E866: 99.17 | F866: 0.00K | G866: -0.0059
A867: 45784 | B867: 99.61 | C867: 99.5 | D867: 99.97 | E867: 99.29 | F867: 0.00K | G867: 0.0038
A868: 45785 | B868: 100.64 | C868: 99.85 | D868: 100.76 | E868: 99.61 | F868: 0.00K | G868: 0.0103
A869: 45786 | B869: 100.34 | C869: 100.64 | D869: 100.86 | E869: 100.09 | G869: -0.003
A870: 45789 | B870: 101.79 | C870: 100.69 | D870: 101.98 | E870: 100.51 | F870: 0.00K | G870: 0.0144
A871: 45790 | B871: 101 | C871: 101.72 | D871: 101.76 | E871: 100.91 | F871: 0.00K | G871: -0.0077
A872: 45791 | B872: 101.04 | C872: 100.95 | D872: 101.14 | E872: 100.27 | F872: 0.00K | G872: 0.0004
A873: 45792 | B873: 100.88 | C873: 100.97 | D873: 101.06 | E873: 100.59 | F873: 0.00K | G873: -0.0016
A874: 45793 | B874: 101.09 | C874: 100.77 | D874: 101.26 | E874: 100.52 | G874: 0.0021
A875: 45796 | B875: 100.43 | C875: 100.9 | D875: 100.9 | E875: 100.06 | F875: 0.00K | G875: -0.0066
A876: 45797 | B876: 100.12 | C876: 100.43 | D876: 100.58 | E876: 100.01 | F876: 0.00K | G876: -0.0031
A877: 45798 | B877: 99.56 | C877: 99.99 | D877: 99.99 | E877: 99.34 | F877: 0.00K | G877: -0.0056
A878: 45799 | B878: 99.96 | C878: 99.64 | D878: 100.12 | E878: 99.44 | F878: 0.00K | G878: 0.004
A879: 45800 | B879: 99.11 | C879: 99.88 | D879: 99.94 | E879: 99.05 | G879: -0.0085
A880: 45803 | B880: 99.11 | C880: 99.09 | D880: 99.16 | E880: 98.69 | F880: 0.00K | G880: 0
A881: 45804 | B881: 99.52 | C881: 98.96 | D881: 99.61 | E881: 98.78 | F881: 0.00K | G881: 0.0041
A882: 45805 | B882: 99.88 | C882: 99.53 | D882: 99.96 | E882: 99.44 | F882: 0.00K | G882: 0.0036
A883: 45806 | B883: 99.28 | C883: 100.54 | D883: 100.54 | E883: 99.22 | F883: 0.00K | G883: -0.006
A884: 45807 | B884: 99.33 | C884: 99.25 | D884: 99.67 | E884: 99.13 | G884: 0.0005
A885: 45810 | B885: 98.71 | C885: 99.41 | D885: 99.42 | E885: 98.61 | F885: 0.00K | G885: -0.0063
A886: 45811 | B886: 99.23 | C886: 98.58 | D886: 99.33 | E886: 98.58 | F886: 0.00K | G886: 0.0053
A887: 45812 | B887: 98.79 | C887: 99.18 | D887: 99.39 | E887: 98.67 | F887: 0.00K | G887: -0.0044
A888: 45813 | B888: 98.74 | C888: 98.8 | D888: 98.94 | E888: 98.35 | F888: 0.00K | G888: -0.0005
A889: 45814 | B889: 99.19 | C889: 98.7 | D889: 99.36 | E889: 98.65 | G889: 0.0045
A890: 45817 | B890: 98.94 | C890: 99.2 | D890: 99.23 | E890: 98.82 | F890: 0.00K | G890: -0.0025
A891: 45818 | B891: 99.1 | C891: 98.98 | D891: 99.39 | E891: 98.86 | F891: 0.00K | G891: 0.0016
...

Sheet WTI原油期货
A1: 日期 | B1: 收盘 | C1: 开盘 | D1: 高 | E1: 低 | F1: 交易量 | G1: 涨跌幅
A2: 44564 | B2: 75.85 | C2: 75.53 | D2: 76.18 | E2: 74.01 | F2: 112.23K | G2: 0.013
A3: 44565 | B3: 76.74 | C3: 75.8 | D3: 77.4 | E3: 75.47 | F3: 156.45K | G3: 0.0117
A4: 44566 | B4: 77.47 | C4: 76.88 | D4: 78.16 | E4: 76.25 | F4: 197.97K | G4: 0.0095
A5: 44567 | B5: 78.88 | C5: 76.79 | D5: 79.56 | E5: 76.28 | F5: 244.00K | G5: 0.0182
A6: 44568 | B6: 78.44 | C6: 79 | D6: 79.82 | E6: 78.07 | F6: 229.28K | G6: -0.0056
A7: 44571 | B7: 77.7 | C7: 78.51 | D7: 78.92 | E7: 77.34 | F7: 210.84K | G7: -0.0094
A8: 44572 | B8: 80.67 | C8: 77.87 | D8: 80.95 | E8: 77.83 | F8: 270.56K | G8: 0.0382
A9: 44573 | B9: 82.02 | C9: 80.71 | D9: 82.41 | E9: 80.55 | F9: 303.16K | G9: 0.0167
A10: 44574 | B10: 81.62 | C10: 82.12 | D10: 82.29 | E10: 80.91 | F10: 289.31K | G10: -0.0049
A11: 44575 | B11: 83.3 | C11: 81.21 | D11: 83.79 | E11: 81.1 | F11: 323.11K | G11: 0.0206
A12: 44577 | B12: 83.83 | C12: 83.78 | D12: 84.09 | E12: 83.68 | G12: 0.0064
A13: 44578 | B13: 83.69 | C13: 83.84 | D13: 83.95 | E13: 82.94 | G13: -0.0017
A14: 44579 | B14: 84.83 | C14: 83.77 | D14: 85.98 | E14: 82.93 | F14: 494.00K | G14: 0.0136
A15: 44580 | B15: 85.8 | C15: 85.89 | D15: 86.79 | E15: 84.99 | F15: 511.05K | G15: 0.0114
A16: 44581 | B16: 85.55 | C16: 85.06 | D16: 87.1 | E16: 84.2 | F16: 532.20K | G16: -0.0029
A17: 44582 | B17: 84.14 | C17: 83.65 | D17: 84.53 | E17: 81.96 | F17: 159.57K | G17: -0.0165
A18: 44585 | B18: 82.41 | C18: 83.84 | D18: 85.1 | E18: 81.06 | F18: 153.83K | G18: -0.0206
A19: 44586 | B19: 84.37 | C19: 83.32 | D19: 84.54 | E19: 82.14 | F19: 223.59K | G19: 0.0238
A20: 44587 | B20: 85.96 | C20: 84.1 | D20: 86.51 | E20: 83.84 | F20: 175.93K | G20: 0.0188
A21: 44588 | B21: 85.29 | C21: 85.71 | D21: 87.08 | E21: 84.9 | F21: 153.94K | G21: -0.0078
A22: 44589 | B22: 85.43 | C22: 86 | D22: 87.36 | E22: 85.06 | F22: 144.85K | G22: 0.0016
A23: 44592 | B23: 86.49 | C23: 85.92 | D23: 86.68 | E23: 84.96 | F23: 144.70K | G23: 0.0124
A24: 44593 | B24: 86.46 | C24: 86.45 | D24: 87.12 | E24: 84.92 | F24: 151.60K | G24: -0.0003
A25: 44594 | B25: 86.69 | C25: 86.64 | D25: 87.93 | E25: 85.56 | F25: 189.90K | G25: 0.0027
... A37: 44610 | B37: 90.21 | C37: 90.06 | D37: 91.07 | E37: 87.46 | F37: 566.36K | G37: 0.0019
A38: 44612 | B38: 91.62 | C38: 91.22 | D38: 91.74 | E38: 91.08 | G38: 0.0156
A39: 44613 | B39: 92.65 | C39: 91.62 | D39: 93.91 | E39: 89.08 | G39: 0.0112
A40: 44614 | B40: 91.91 | C40: 91.32 | D40: 94.95 | E40: 89.06 | F40: 789.04K | G40: -0.008
A41: 44615 | B41: 90.69 | C41: 90.31 | D41: 92.36 | E41: 89.34 | F41: 150.13K | G41: -0.0133
A42: 44616 | B42: 90.94 | C42: 91.08 | D42: 98.44 | E42: 89.65 | F42: 289.12K | G42: 0.0028
A43: 44617 | B43: 89.89 | C43: 91.48 | D43: 93.73 | E43: 88.49 | F43: 160.46K | G43: -0.0115
A44: 44620 | B44: 93.5 | C44: 92.97 | D44: 96.92 | E44: 92.42 | F44: 176.43K | G44: 0.0402
A45: 44621 | B45: 100.21 | C45: 93.88 | D45: 103.06 | E45: 93.21 | F45: 285.55K | G45: 0.0718
A46: 44622 | B46: 107.06 | C46: 103.43 | D46: 108.91 | E46: 101.86 | F46: 219.17K | G46: 0.0684
A47: 44623 | B47: 104.61 | C47: 107.27 | D47: 112.65 | E47: 103.14 | F47: 190.66K | G47: -0.0229
A48: 44624 | B48: 112.11 | C48: 105.04 | D48: 112.54 | E48: 104.36 | F48: 167.99K | G48: 0.0717
A49: 44627 | B49: 115.8 | C49: 116.03 | D49: 126.42 | E49: 111.87 | F49: 202.56K | G49: 0.0329
A50: 44628 | B50: 119.65 | C50: 116.98 | D50: 124.98 | E50: 113.66 | F50: 200.16K | G50: 0.0332
A51: 44629 | B51: 105.05 | C51: 120.66 | D51: 122.73 | E51: 99.55 | F51: 249.98K | G51: -0.122
...

Sheet 黄金期货
A1: 日期 | B1: 收盘 | C1: 开盘 | D1: 高 | E1: 低 | F1: 交易量 | G1: 涨跌幅
A2: 44564 | B2: 1800.1 | C2: 1830.1 | D2: 1833 | E2: 1798.2 | F2: 168.31K | G2: -0.0156
A3: 44565 | B3: 1814.6 | C3: 1801.1 | D3: 1817.2 | E3: 1798.1 | F3: 167.71K | G3: 0.0081
A4: 44566 | B4: 1825.1 | C4: 1815.2 | D4: 1830.7 | E4: 1808.2 | F4: 173.34K | G4: 0.0058
A5: 44567 | B5: 1789.2 | C5: 1810.6 | D5: 1811.6 | E5: 1785.4 | F5: 238.64K | G5: -0.0197
A6: 44568 | B6: 1797.4 | C6: 1791 | D6: 1798.4 | E6: 1781.3 | F6: 238.93K | G6: 0.0046
A7: 44571 | B7: 1798.8 | C7: 1796.4 | D7: 1802 | E7: 1789.3 | F7: 173.04K | G7: 0.0008
A8: 44572 | B8: 1818.5 | C8: 1801.3 | D8: 1823.1 | E8: 1799.7 | F8: 184.15K | G8: 0.011
A9: 44573 | B9: 1827.3 | C9: 1821.3 | D9: 1828.2 | E9: 1814.4 | F9: 192.98K | G9: 0.0048
A10: 44574 | B10: 1821.4 | C10: 1825.7 | D10: 1828.3 | E10: 1811.8 | F10: 215.52K | G10: -0.0032
A11: 44575 | B11: 1816.5 | C11: 1822.1 | D11: 1829.3 | E11: 1814.2 | F11: 174.94K | G11: -0.0027
A12: 44578 | B12: 1812.4 | C12: 1818.7 | D12: 1822.9 | E12: 1804.7 | F12: 362.94K | G12: -0.0023
A13: 44579 | B13: 1812.4 | C13: 1818.7 | D13: 1822.9 | E13: 1804.7 | F13: 362.94K | G13: 0
... A636: 45461 | B636: 2334.8 | C636: 2323.3 | D636: 2334.5 | E636: 2309.1 | F636: 0.39K | G636: 0.0077
A637: 45462 | B637: 2343 | C637: 2342.95 | D637: 2349.65 | E637: 2338.6 | G637: 0.0035
A638: 45463 | B638: 2357 | C638: 2331.4 | D638: 2367 | E638: 2327 | F638: 0.83K | G638: 0.006
A639: 45464 | B639: 2319.1 | C639: 2361.5 | D639: 2370 | E639: 2318 | F639: 0.60K | G639: -0.0161
A640: 45467 | B640: 2332.4 | C640: 2322.1 | D640: 2334.7 | E640: 2318 | F640: 0.60K | G640: 0.0057
A641: 45468 | B641: 2318.4 | C641: 2334.4 | D641: 2336.2 | E641: 2314.8 | F641: 1.26K | G641: -0.006
A642: 45469 | B642: 2301 | C642: 2318.8 | D642: 2320.5 | E642: 2292.9 | F642: 0.99K | G642: -0.0075
A643: 45470 | B643: 2336.6 | C643: 2309.4 | D643: 2342 | E643: 2306.8 | F643: 140.23K | G643: 0.0155
A644: 45471 | B644: 2339.6 | C644: 2338.6 | D644: 2350.6 | E644: 2329.7 | F644: 135.38K | G644: 0.0013
A645: 45474 | B645: 2338.9 | C645: 2336.2 | D645: 2348.8 | E645: 2328.2 | F645: 142.60K | G645: -0.0003
A646: 45475 | B646: 2333.4 | C646: 2341.6 | D646: 2346.1 | E646: 2327.4 | F646: 153.71K | G646: -0.0024
A647: 45476 | B647: 2369.4 | C647: 2338.6 | D647: 2374.5 | E647: 2335.7 | F647: 193.64K | G647: 0.0154
A648: 45477 | B648: 2364.6 | C648: 2367.2 | D648: 2371.05 | E648: 2359.35 | G648: -0.002
A649: 45478 | B649: 2397.7 | C649: 2365.8 | D649: 2401.5 | E649: 2356 | F649: 293.25K | G649: 0.014
A650: 45481 | B650: 2363.5 | C650: 2396.2 | D650: 2399.3 | E650: 2358.3 | F650: 240.78K | G650: -0.0143
A651: 45482 | B651: 2367.9 | C651: 2366.5 | D651: 2378.3 | E651: 2356 | F651: 252.49K | G651: 0.0019
A652: 45483 | B652: 2379.7 | C652: 2371 | D652: 2393.4 | E652: 2369.7 | F652: 163.90K | G652: 0.005
A653: 45484 | B653: 2421.9 | C653: 2377.4 | D653: 2430.4 | E653: 2376.8 | F653: 303.52K | G653: 0.0177
A654: 45485 | B654: 2420.7 | C654: 2421 | D654: 2423.2 | E654: 2396.1 | F654: 220.93K | G654: -0.0005
A655: 45488 | B655: 2428.9 | C655: 2419.3 | D655: 2445 | E655: 2406.1 | F655: 193.54K | G655: 0.0034
A656: 45489 | B656: 2467.8 | C656: 2427.1 | D656: 2474.5 | E656: 2424.5 | F656: 246.09K | G656: 0.016
A657: 45490 | B657: 2459.9 | C657: 2473.2 | D657: 2488.4 | E657: 2455.5 | F657: 259.54K | G657: -0.0032
A658: 45491 | B658: 2456.4 | C658: 2462.5 | D658: 2478.5 | E658: 2442.9 | F658: 192.77K | G658: -0.0014
A659: 45492 | B659: 2399.1 | C659: 2448 | D659: 2448.4 | E659: 2395.7 | F659: 254.41K | G659: -0.0233
A660: 45495 | B660: 2394.7 | C660: 2403.7 | D660: 2414.4 | E660: 2385.2 | F660: 197.56K | G660: -0.0018
... A943: 45898 | B943: 3516.1 | C943: 3477.2 | D943: 3518.5 | E943: 3463 | F943: 188.55K | G943: 0.012
A944: 45900 | B944: 3512 | C944: 3517.65 | D944: 3517.65 | E944: 3509.7 | G944: -0.0012
...

Sheet 天然气期货
A1: 日期 | B1: 收盘 | C1: 开盘 | D1: 高 | E1: 低 | F1: 交易量 | G1: 涨跌幅
A2: 44564 | B2: 3.678 | C2: 3.554 | D2: 3.709 | E2: 3.5 | F2: 52.87K | G2: 0.034
A3: 44565 | B3: 3.582 | C3: 3.674 | D3: 3.777 | E3: 3.573 | F3: 56.26K | G3: -0.0261
A4: 44566 | B4: 3.71 | C4: 3.611 | D4: 3.738 | E4: 3.591 | F4: 48.91K | G4: 0.0357
A5: 44567 | B5: 3.67 | C5: 3.679 | D5: 3.757 | E5: 3.647 | F5: 45.46K | G5: -0.0108
A6: 44568 | B6: 3.726 | C6: 3.716 | D6: 3.803 | E6: 3.664 | F6: 66.76K | G6: 0.0153
A7: 44571 | B7: 3.834 | C7: 3.91 | D7: 3.966 | E7: 3.764 | F7: 89.08K | G7: 0.029
A8: 44572 | B8: 3.968 | C8: 3.868 | D8: 3.98 | E8: 3.787 | F8: 76.68K | G8: 0.035
A9: 44573 | B9: 4.327 | C9: 3.948 | D9: 4.356 | E9: 3.926 | F9: 125.21K | G9: 0.0905
A10: 44574 | B10: 4.005 | C10: 4.296 | D10: 4.329 | E10: 3.99 | F10: 115.34K | G10: -0.0744
A11: 44575 | B11: 4.081 | C11: 4.01 | D11: 4.097 | E11: 3.933 | F11: 67.72K | G11: 0.019
A12: 44577 | B12: 4.335 | C12: 4.338 | D12: 4.35 | E12: 4.323 | G12: 0.0622
A13: 44578 | B13: 4.276 | C13: 4.33 | D13: 4.353 | E13: 4.216 | G13: -0.0136
A14: 44579 | B14: 4.048 | C14: 4.143 | D14: 4.18 | E14: 4.002 | F14: 77.07K | G14: -0.0533
A15: 44580 | B15: 3.845 | C15: 4.071 | D15: 4.119 | E15: 3.834 | F15: 84.60K | G15: -0.0501
A16: 44581 | B16: 3.649 | C16: 3.834 | D16: 3.868 | E16: 3.629 | F16: 97.44K | G16: -0.051
A17: 44582 | B17: 3.782 | C17: 3.68 | D17: 3.829 | E17: 3.669 | F17: 75.32K | G17: 0.0364
A18: 44585 | B18: 3.875 | C18: 3.709 | D18: 3.912 | E18: 3.693 | F18: 90.92K | G18: 0.0246
A19: 44586 | B19: 3.894 | C19: 3.811 | D19: 3.919 | E19: 3.761 | F19: 91.17K | G19: 0.0049
A20: 44587 | B20: 4.036 | C20: 3.885 | D20: 4.194 | E20: 3.856 | F20: 158.50K | G20: 0.0365
A21: 44588 | B21: 4.283 | C21: 4 | D21: 4.42 | E21: 3.99 | F21: 193.25K | G21: 0.0612
A22: 44589 | B22: 4.473 | C22: 4.222 | D22: 4.629 | E22: 4.192 | F22: 137.04K | G22: 0.0444
A23: 44592 | B23: 4.675 | C23: 4.637 | D23: 4.803 | E23: 4.533 | F23: 81.26K | G23: 0.0452
A24: 44593 | B24: 4.573 | C24: 4.696 | D24: 4.736 | E24: 4.474 | F24: 66.06K | G24: -0.0218
A25: 44594 | B25: 5.044 | C25: 4.681 | D25: 5.053 | E25: 4.664 | F25: 164.67K | G25: 0.103
... A37: 44610 | B37: 4.377 | C37: 4.451 | D37: 4.585 | E37: 4.306 | F37: 98.02K | G37: -0.012
A38: 44612 | B38: 4.579 | C38: 4.529 | D38: 4.598 | E38: 4.527 | G38: 0.0462
A39: 44613 | B39: 4.705 | C39: 4.58 | D39: 4.745 | E39: 4.52 | G39: 0.0275
A40: 44614 | B40: 4.461 | C40: 4.505 | D40: 4.746 | E40: 4.409 | F40: 141.92K | G40: -0.0519
A41: 44615 | B41: 4.593 | C41: 4.466 | D41: 4.685 | E41: 4.437 | F41: 136.53K | G41: 0.0296
A42: 44616 | B42: 4.641 | C42: 4.592 | D42: 4.938 | E42: 4.555 | F42: 184.11K | G42: 0.0105
A43: 44617 | B43: 4.485 | C43: 4.591 | D43: 4.724 | E43: 4.435 | F43: 48.17K | G43: -0.0336
A44: 44620 | B44: 4.42 | C44: 4.63 | D44: 4.7 | E44: 4.392 | F44: 51.67K | G44: -0.0145
A45: 44621 | B45: 4.598 | C45: 4.425 | D45: 4.649 | E45: 4.361 | F45: 61.82K | G45: 0.0403
A46: 44622 | B46: 4.787 | C46: 4.631 | D46: 4.928 | E46: 4.63 | F46: 80.45K | G46: 0.0411
A47: 44623 | B47: 4.736 | C47: 4.813 | D47: 4.949 | E47: 4.653 | F47: 86.53K | G47: -0.0107
A48: 44624 | B48: 5.036 | C48: 4.763 | D48: 5.06 | E48: 4.758 | F48: 59.64K | G48: 0.0633
A49: 44627 | B49: 4.858 | C49: 5.057 | D49: 5.199 | E49: 4.809 | F49: 71.58K | G49: -0.0353
A50: 44628 | B50: 4.563 | C50: 4.848 | D50: 4.909 | E50: 4.541 | F50: 87.82K | G50: -0.0607
A51: 44629 | B51: 4.561 | C51: 4.615 | D51: 4.664 | E51: 4.488 | F51: 52.78K | G51: -0.0004
...

Sheet 港存及港价
A1: 日期 | B1: 港口库存（万吨） | C1: 镇江港颗粒硫磺价格（元/吨）
A2: 45293 | B2: 266 | C2: 930
A3: 45294 | B3: 263 | C3: 930
A4: 45295 | B4: 262 | C4: 920
A5: 45296 | B5: 262 | C5: 910
A6: 45299 | B6: 260 | C6: 900
A7: 45300 | B7: 265 | C7: 880
A8: 45301 | B8: 268 | C8: 860
A9: 45302 | B9: 266 | C9: 850
A10: 45303 | B10: 264 | C10: 845
A11: 45306 | B11: 263 | C11: 840
A12: 45307 | B12: 262 | C12: 830
A13: 45308 | B13: 265 | C13: 820
... A423: 45910 | B423: 241 | C423: 2620
