Workbook

Sheet 打印-表格（近5年）
A1: 二铵、硫磺、磷矿、北方煤价格走势（17年-22年）
A2: 二铵、硫磺、磷矿石、北方煤18-22年历史价格 （1）二铵均价2873、最高价5705（22年7月）、最低价1987（20年2月、3月）； （2）硫磺均价1378、最高价4064（22年5月）、最低价554（19年11月）； （3）27%磷矿均价469、最高价958（22年7月、8月）、最低价328（20年9月、10月）； （4）兰花煤均价1045、最高价2309（21年10月）、最低价693（20年8月、9月）。 二铵与硫磺、磷矿、北方煤18-22年历史价格比值 （1）二铵与硫磺价格平均比值2.39，最高比值4.74（22年8月）、最低比值1.23（22年4月）； （2）二铵与磷矿价格平均比值6.14，最高比值8.07（21年4月）、最低比值5.37（20年2月、3月）； （3）二铵与北方煤价格平均比值2.78，最高比值3.83（22年7月）、最低比值1.62（21年10月）。
A3: 产品/原料 | B3: 平均 | C3: 18年1月 | D3: 18年2月 | E3: 18年3月 | F3: 18年4月 | G3: 18年5月 | H3: 18年6月 | I3: 18年7月 | J3: 18年8月 | K3: 18年9月 | L3: 18年10月 | M3: 18年11月 | N3: 18年12月 | O3: 19年1月 | P3: 19年2月 | Q3: 19年3月 | R3: 19年4月 | S3: 19年5月 | T3: 19年6月 | U3: 19年7月 | V3: 19年8月 | W3: 19年9月 | X3: 19年10月 | Y3: 19年11月 | Z3: 19年12月 | AA3: 20年1月 | AB3: 20年2月 | AC3: 20年3月 | AD3: 20年4月 | AE3: 20年5月 | AF3: 20年6月 | AG3: 20年7月 | AH3: 20年8月 | AI3: 20年9月 | AJ3: 20年10月 | AK3: 20年11月 | AL3: 20年12月 | AM3: 21年1月 | AN3: 21年2月 | AO3: 21年3月 | AP3: 21年4月 | AQ3: 21年5月 | AR3: 21年6月 | AS3: 21年7月 | AT3: 21年8月 | AU3: 21年9月 | AV3: 21年10月 | AW3: 21年11月 | AX3: 21年12月 | AY3: 22年1月 | AZ3: 22年2月 | BA3: 22年3月 | BB3: 22年4月 | BC3: 22年5月 | BD3: 22年6月 | BE3: 22年7月 | BF3: 22年8月
B4: =AVERAGE(C4:BF4) -> 2873.4419 | C4: ='走势图 (近5年3张)'!AX2 -> 2501.2773 | D4: ='走势图 (近5年3张)'!AY2 -> 2526.6649 | E4: ='走势图 (近5年3张)'!AZ2 -> 2597.1353 | F4: ='走势图 (近5年3张)'!BA2 -> 2548.6285 | G4: ='走势图 (近5年3张)'!BB2 -> 2565.6194 | H4: ='走势图 (近5年3张)'!BC2 -> 2575.9278 | I4: ='走势图 (近5年3张)'!BD2 -> 2678.8684 | J4: ='走势图 (近5年3张)'!BE2 -> 2733.1973 | ... BF4: ='走势图 (近5年3张)'!DA2 -> 5154
B5: =AVERAGE(C5:BF5) -> 1377.6249 | C5: ='走势图 (近5年3张)'!AX4 -> 1214 | D5: ='走势图 (近5年3张)'!AY4 -> 1229 | E5: ='走势图 (近5年3张)'!AZ4 -> 1147 | F5: ='走势图 (近5年3张)'!BA4 -> 1089 | G5: ='走势图 (近5年3张)'!BB4 -> 1157 | H5: ='走势图 (近5年3张)'!BC4 -> 1178 | I5: ='走势图 (近5年3张)'!BD4 -> 1223 | J5: ='走势图 (近5年3张)'!BE4 -> 1358 | ... BF5: ='走势图 (近5年3张)'!DA4 -> 1086.5217
B6: =AVERAGE(C6:BF6) -> 2.3873798 | C6: =C4/C5 -> 2.0603602 | D6: =D4/D5 -> 2.0558705 | E6: =E4/E5 -> 2.2642854 | F6: =F4/F5 -> 2.3403383 | G6: =G4/G5 -> 2.2174757 | H6: =H4/H5 -> 2.1866959 | I6: =I4/I5 -> 2.1904075 | J6: =J4/J5 -> 2.0126637 | ... BF6: =BF4/BF5 -> 4.7435774
A9: 二铵 | B9: =AVERAGE(C9:BF9) -> 2873.4419 | C9: ='走势图 (近5年3张)'!AX8 -> 2501.2773 | D9: ='走势图 (近5年3张)'!AY8 -> 2526.6649 | E9: ='走势图 (近5年3张)'!AZ8 -> 2597.1353 | F9: ='走势图 (近5年3张)'!BA8 -> 2548.6285 | G9: ='走势图 (近5年3张)'!BB8 -> 2565.6194 | H9: ='走势图 (近5年3张)'!BC8 -> 2575.9278 | I9: ='走势图 (近5年3张)'!BD8 -> 2678.8684 | J9: ='走势图 (近5年3张)'!BE8 -> 2733.1973 | ... BF9: ='走势图 (近5年3张)'!DA8 -> 5154
B10: =AVERAGE(C10:BF10) -> 468.87857 | C10: ='走势图 (近5年3张)'!AX9 -> 430 | D10: ='走势图 (近5年3张)'!AY9 -> 430 | E10: ='走势图 (近5年3张)'!AZ9 -> 430 | F10: ='走势图 (近5年3张)'!BA9 -> 430 | G10: ='走势图 (近5年3张)'!BB9 -> 430 | H10: ='走势图 (近5年3张)'!BC9 -> 430 | I10: ='走势图 (近5年3张)'!BD9 -> 430 | J10: ='走势图 (近5年3张)'!BE9 -> 430 | ... BF10: ='走势图 (近5年3张)'!DA9 -> 958
B11: =AVERAGE(C11:BF11) -> 6.1395428 | C11: =C9/C10 -> 5.816924 | D11: =D9/D10 -> 5.8759648 | E11: =E9/E10 -> 6.0398496 | F11: =F9/F10 -> 5.9270429 | G11: =G9/G10 -> 5.9665568 | H11: =H9/H10 -> 5.9905297 | I11: =I9/I10 -> 6.2299266 | J11: =J9/J10 -> 6.3562728 | ... BF11: =BF9/BF10 -> 5.3799582
B13: =AVERAGE(C13:BF13) -> 2873.4419 | C13: ='走势图 (近5年3张)'!AX13 -> 2501.2773 | D13: ='走势图 (近5年3张)'!AY13 -> 2526.6649 | E13: ='走势图 (近5年3张)'!AZ13 -> 2597.1353 | F13: ='走势图 (近5年3张)'!BA13 -> 2548.6285 | G13: ='走势图 (近5年3张)'!BB13 -> 2565.6194 | H13: ='走势图 (近5年3张)'!BC13 -> 2575.9278 | I13: ='走势图 (近5年3张)'!BD13 -> 2678.8684 | J13: ='走势图 (近5年3张)'!BE13 -> 2733.1973 | ... BF13: ='走势图 (近5年3张)'!DA13 -> 5154
A15: 北方煤（兰花） | B15: =AVERAGE(C15:BF15) -> 1045.4749 | C15: ='走势图 (近5年3张)'!AX14 -> 964 | D15: ='走势图 (近5年3张)'!AY14 -> 984 | E15: ='走势图 (近5年3张)'!AZ14 -> 984 | F15: ='走势图 (近5年3张)'!BA14 -> 964 | G15: ='走势图 (近5年3张)'!BB14 -> 914 | H15: ='走势图 (近5年3张)'!BC14 -> 911 | I15: ='走势图 (近5年3张)'!BD14 -> 911 | J15: ='走势图 (近5年3张)'!BE14 -> 901 | ... BF15: ='走势图 (近5年3张)'!DA14 -> 1443
B16: =AVERAGE(C16:BF16) -> 2.7780618 | C16: =C13/C15 -> 2.594686 | D16: =D13/D15 -> 2.5677489 | E16: =E13/E15 -> 2.6393652 | F16: =F13/F15 -> 2.6438055 | G16: =G13/G15 -> 2.8070235 | H16: =H13/H15 -> 2.8275826 | I16: =I13/I15 -> 2.9405801 | J16: =J13/J15 -> 3.0335153 | ... BF16: =BF13/BF15 -> 3.5717256

Sheet 打印-表格（分月分季度)
A1: 二铵、硫磺、磷矿价格走势（17年-21年）
A2: 品种 | B2: 年份 | C2: 分季度 | G2: 分月
C3: 一季度 | D3: 二季度 | E3: 三季度 | F3: 四季度 | G3: 1月 | H3: 2月 | I3: 3月 | J3: 4月 | K3: 5月 | L3: 6月 | M3: 7月 | N3: 8月 | O3: 9月 | P3: 10月 | Q3: 11月 | R3: 12月
A4: 二铵 | B4: 17年 | C4: =AVERAGE(G4:I4) -> 2262.9383 | D4: =AVERAGE(J4:L4) -> 2344.0732 | E4: =AVERAGE(M4:O4) -> 2230.252 | F4: =AVERAGE(P4:R4) -> 2345.0839 | G4: 2134.8937 | H4: 2300.4024 | I4: 2353.5189 | J4: 2376.9914 | K4: 2370.111 | L4: 2285.1173 | M4: 2235.389 | N4: 2225.4675 | O4: 2229.8995 | P4: 2235.7325 | Q4: 2329.2131 | R4: 2470.3062
B5: 18年 | C5: =AVERAGE(G5:I5) -> 2541.6925 | D5: =AVERAGE(J5:L5) -> 2563.3919 | E5: =AVERAGE(M5:O5) -> 2719.1092 | F5: =AVERAGE(P5:R5) -> 2714.2114 | G5: 2501.2773 | H5: 2526.6649 | I5: 2597.1353 | J5: 2548.6285 | K5: 2565.6194 | L5: 2575.9278 | M5: 2678.8684 | N5: 2733.1973 | O5: 2745.262 | P5: 2742.6343 | Q5: 2700 | R5: 2700
B6: 19年 | C6: =AVERAGE(G6:I6) -> 2586.4639 | D6: =AVERAGE(J6:L6) -> 2449.4886 | E6: =AVERAGE(M6:O6) -> 2205.1619 | F6: =AVERAGE(P6:R6) -> 2101.4259 | G6: 2614 | H6: 2625 | I6: 2520.3918 | J6: 2512.1307 | K6: 2429.0092 | L6: 2407.3258 | M6: 2214.2749 | N6: 2214.1737 | O6: 2187.0372 | P6: 2139.2073 | Q6: 2103.8387 | R6: 2061.2315
B7: 20年 | C7: =AVERAGE(G7:I7) -> 2019.9458 | D7: =AVERAGE(J7:L7) -> 2068.113 | E7: =AVERAGE(M7:O7) -> 2119.1809 | F7: =AVERAGE(P7:R7) -> 2274.3369 | G7: 2085.8565 | H7: 1986.9905 | I7: 1986.9905 | J7: 2071.5497 | K7: 2060.8699 | L7: 2071.9194 | M7: 2098.8153 | N7: 2082.682 | O7: 2176.0454 | P7: 2238.3727 | Q7: 2273.7149 | R7: 2310.9231
B8: 21年 | C8: =AVERAGE(G8:I8) -> 2521.2251 | D8: =AVERAGE(J8:L8) -> 3260.5616 | E8: =AVERAGE(M8:O8) -> 3553.8654 | F8: =AVERAGE(P8:R8) -> 3604.9636 | G8: 2365.1228 | H8: 2471.1848 | I8: 2727.3676 | J8: 3293.7439 | K8: 3225.7658 | L8: 3262.175 | M8: 3373.0201 | N8: 3508.2873 | O8: 3780.2887 | P8: 3742.6374 | Q8: 3536.1539 | R8: 3536.0994
B9: 22年 | C9: =AVERAGE(G9:I9) -> 3824.4451 | D9: =AVERAGE(J9:L9) -> 4890.3333 | E9: =AVERAGE(M9:O9) -> 5077.3333 | F9: 3900 | G9: 3635.9425 | H9: 3566.1321 | I9: 4271.2606 | J9: 4362 | K9: 5029 | L9: 5280 | M9: 5705 | N9: 5154 | O9: 4373 | P9: 3900 | Q9: 3900 | R9: 3900
B10: 平均 | C10: =AVERAGE(C4:C8) -> 2386.4531 | D10: =AVERAGE(D4:D8) -> 2537.1256 | E10: =AVERAGE(E4:E8) -> 2565.5139 | F10: =AVERAGE(F4:F8) -> 2608.0043 | G10: =AVERAGE(G4:G8) -> 2340.2301 | H10: =AVERAGE(H4:H8) -> 2382.0485 | I10: =AVERAGE(I4:I8) -> 2437.0808 | J10: =AVERAGE(J4:J8) -> 2560.6088 | ... R10: =AVERAGE(R4:R8) -> 2615.712
A11: 硫磺 | B11: 17年 | C11: =AVERAGE(G11:I11) -> 925.66667 | D11: =AVERAGE(J11:L11) -> 847.66667 | E11: =AVERAGE(M11:O11) -> 1006.6667 | F11: =AVERAGE(P11:R11) -> 1459.6667 | G11: 917 | H11: 937 | I11: 923 | J11: 833 | K11: 843 | L11: 867 | M11: 932 | N11: 1013 | O11: 1075 | P11: 1416 | Q11: 1632 | R11: 1331
B12: 18年 | C12: =AVERAGE(G12:I12) -> 1196.6667 | D12: =AVERAGE(J12:L12) -> 1141.3333 | E12: =AVERAGE(M12:O12) -> 1366 | F12: =AVERAGE(P12:R12) -> 1392.5 | G12: 1214 | H12: 1229 | I12: 1147 | J12: 1089 | K12: 1157 | L12: 1178 | M12: 1223 | N12: 1358 | O12: 1517 | P12: 1489 | Q12: 1428 | R12: 1260.5
B13: 19年 | C13: =AVERAGE(G13:I13) -> 1105.1567 | D13: =AVERAGE(J13:L13) -> 1008.0905 | E13: =AVERAGE(M13:O13) -> 775.31989 | F13: =AVERAGE(P13:R13) -> 585.01025 | G13: 1163.57 | H13: 1116 | I13: 1035.9 | J13: 1027.73 | K13: 1002.8571 | L13: 993.68421 | M13: 871.08696 | N13: 782.27273 | O13: 672.6 | P13: 632.36842 | Q13: 553.57143 | R13: 569.09091
B14: 20年 | C14: =AVERAGE(G14:I14) -> 655.52083 | D14: =AVERAGE(J14:L14) -> 663.55073 | E14: =AVERAGE(M14:O14) -> 691.64941 | F14: =AVERAGE(P14:R14) -> 854.33877 | G14: 626.5625 | H14: 641.13636 | I14: 698.86364 | J14: 628.40909 | K14: 671.05263 | L14: 691.19048 | M14: 660.86957 | N14: 681.90476 | O14: 732.17391 | P14: 776.17647 | Q14: 836.36364 | R14: 950.47619
B15: 21年 | C15: =AVERAGE(G15:I15) -> 1323.5168 | D15: =AVERAGE(J15:L15) -> 1554.1103 | E15: =AVERAGE(M15:O15) -> 1785.6061 | F15: =AVERAGE(P15:R15) -> 2113.9735 | G15: 1122.75 | H15: 1468.2353 | I15: 1379.5652 | J15: 1450 | K15: 1584.4737 | L15: 1627.8571 | M15: 1614.3182 | N15: 1804.0909 | O15: 1938.4091 | P15: 1967.0588 | Q15: 2031.8182 | R15: 2343.0435
B16: 22年 | C16: =AVERAGE(G16:I16) -> 2785.5278 | D16: =AVERAGE(J16:L16) -> 3724.1905 | E16: =AVERAGE(M16:O16) -> 1370.2692 | F16: 1200 | G16: 2491.25 | H16: 2599.3333 | I16: 3266 | J16: 3540.4762 | K16: 4064 | L16: 3568.0952 | M16: 1894.2857 | N16: 1086.5217 | O16: 1130 | P16: 1200 | Q16: 1200 | R16: 1200
B17: 平均 | C17: =AVERAGE(C11:C15) -> 1041.3055 | D17: =AVERAGE(D11:D15) -> 1042.9503 | E17: =AVERAGE(E11:E15) -> 1125.0484 | F17: =AVERAGE(F11:F15) -> 1281.0978 | G17: =AVERAGE(G11:G15) -> 1008.7765 | H17: =AVERAGE(H11:H15) -> 1078.2743 | I17: =AVERAGE(I11:I15) -> 1036.8658 | J17: =AVERAGE(J11:J15) -> 1005.6278 | ... R17: =AVERAGE(R11:R15) -> 1290.8221
A18: 磷矿 | B18: 17年 | C18: =AVERAGE(G18:I18) -> 350 | D18: =AVERAGE(J18:L18) -> 355 | E18: =AVERAGE(M18:O18) -> 355 | F18: =AVERAGE(P18:R18) -> 380 | G18: 340 | H18: 355 | I18: 355 | J18: 355 | K18: 355 | L18: 355 | M18: 355 | N18: 355 | O18: 355 | P18: 355 | Q18: 355 | R18: 430
B19: 18年 | C19: =AVERAGE(G19:I19) -> 430 | D19: =AVERAGE(J19:L19) -> 430 | E19: =AVERAGE(M19:O19) -> 430 | F19: =AVERAGE(P19:R19) -> 460 | G19: 430 | H19: 430 | I19: 430 | J19: 430 | K19: 430 | L19: 430 | M19: 430 | N19: 430 | O19: 430 | P19: 430 | Q19: 450 | R19: 500
B20: 19年 | C20: =AVERAGE(G20:I20) -> 453.33333 | D20: =AVERAGE(J20:L20) -> 420 | E20: =AVERAGE(M20:O20) -> 393.33333 | F20: =AVERAGE(P20:R20) -> 373.33333 | G20: 470 | H20: 470 | I20: 420 | J20: 420 | K20: 420 | L20: 420 | M20: 400 | N20: 400 | O20: 380 | P20: 380 | Q20: 370 | R20: 370
B21: 20年 | C21: =AVERAGE(G21:I21) -> 370 | D21: =AVERAGE(J21:L21) -> 338 | E21: =AVERAGE(M21:O21) -> 334.66667 | F21: =AVERAGE(P21:R21) -> 348 | G21: 370 | H21: 370 | I21: 370 | J21: 338 | K21: 338 | L21: 338 | M21: 338 | N21: 338 | O21: 328 | P21: 328 | Q21: 358 | R21: 358
B22: 21年 | C22: =AVERAGE(G22:I22) -> 358 | D22: =AVERAGE(J22:L22) -> 451.33333 | E22: =AVERAGE(M22:O22) -> 558 | F22: =AVERAGE(P22:R22) -> 608 | G22: 358 | H22: 358 | I22: 358 | J22: 408 | K22: 458 | L22: 488 | M22: 508 | N22: 558 | O22: 608 | P22: 608 | Q22: 608 | R22: 608
B23: 22年 | C23: =AVERAGE(G23:I23) -> 608 | D23: =AVERAGE(J23:L23) -> 749.73333 | E23: =AVERAGE(M23:O23) -> 958 | F23: 800 | G23: 608 | H23: 608 | I23: 608 | J23: 645.6 | K23: 745.6 | L23: 858 | M23: 958 | N23: 958 | O23: 958 | P23: 800 | Q23: 800 | R23: 800
B24: 平均 | C24: =AVERAGE(C18:C22) -> 392.26667 | D24: =AVERAGE(D18:D22) -> 398.86667 | E24: =AVERAGE(E18:E22) -> 414.2 | F24: =AVERAGE(F18:F22) -> 433.86667 | G24: =AVERAGE(G18:G22) -> 393.6 | H24: =AVERAGE(H18:H22) -> 396.6 | I24: =AVERAGE(I18:I22) -> 386.6 | J24: =AVERAGE(J18:J22) -> 390.2 | ... R24: =AVERAGE(R18:R22) -> 453.2

Sheet 打印-走势图（4张18-22）
A1: 二铵、硫磺、磷矿、北方煤价格走势（18年-22年）
A2: 品种 | B2: 年份 | C2: 1月 | D2: 2月 | E2: 3月 | F2: 4月 | G2: 5月 | H2: 6月 | I2: 7月 | J2: 8月 | K2: 9月 | L2: 10月 | M2: 11月 | N2: 12月
A3: 二铵 | B3: 18年 | C3: 2501.2773 | D3: 2526.6649 | E3: 2597.1353 | F3: 2548.6285 | G3: 2565.6194 | H3: 2575.9278 | I3: 2678.8684 | J3: 2733.1973 | K3: 2745.262 | L3: 2742.6343 | M3: 2700 | N3: 2700
B4: 19年 | C4: 2614 | D4: 2625 | E4: 2520.3918 | F4: 2512.1307 | G4: 2429.0092 | H4: 2407.3258 | I4: 2214.2749 | J4: 2214.1737 | K4: 2187.0372 | L4: 2139.2073 | M4: 2103.8387 | N4: 2061.2315
B5: 20年 | C5: 2085.8565 | D5: 1986.9905 | E5: 1986.9905 | F5: 2071.5497 | G5: 2060.8699 | H5: 2071.9194 | I5: 2098.8153 | J5: 2082.682 | K5: 2176.0454 | L5: 2238.3727 | M5: 2273.7149 | N5: 2310.9231
B6: 21年 | C6: 2365.1228 | D6: 2471.1848 | E6: 2727.3676 | F6: 3293.7439 | G6: 3225.7658 | H6: 3262.175 | I6: 3373.0201 | J6: 3508.2873 | K6: 3780.2887 | L6: 3742.6374 | M6: 3536.1539 | N6: 3536.0994
B7: 22年 | C7: 3635.9425 | D7: 3566.1321 | E7: 4271.2606 | F7: 4362 | G7: 5029 | H7: 5280 | I7: 5705 | J7: 5154
A8: 硫磺 | B8: 18年 | C8: 1214 | D8: 1229 | E8: 1147 | F8: 1089 | G8: 1157 | H8: 1178 | I8: 1223 | J8: 1358 | K8: 1517 | L8: 1489 | M8: 1428 | N8: 1260.5
B9: 19年 | C9: 1163.57 | D9: 1116 | E9: 1035.9 | F9: 1027.73 | G9: 1002.8571 | H9: 993.68421 | I9: 871.08696 | J9: 782.27273 | K9: 672.6 | L9: 632.36842 | M9: 553.57143 | N9: 569.09091
B10: 20年 | C10: 626.5625 | D10: 641.13636 | E10: 698.86364 | F10: 628.40909 | G10: 671.05263 | H10: 691.19048 | I10: 660.86957 | J10: 681.90476 | K10: 732.17391 | L10: 776.17647 | M10: 836.36364 | N10: 950.47619
B11: 21年 | C11: 1122.75 | D11: 1468.2353 | E11: 1379.5652 | F11: 1450 | G11: 1584.4737 | H11: 1627.8571 | I11: 1614.3182 | J11: 1804.0909 | K11: 1938.4091 | L11: 1967.0588 | M11: 2031.8182 | N11: 2343.0435
B12: 22年 | C12: 2491.25 | D12: 2599.3333 | E12: 3266 | F12: 3540.4762 | G12: 4064 | H12: 3568.0952 | I12: 1894.2857 | J12: 1086.5217
A13: 磷矿 | B13: 18年 | C13: 430 | D13: 430 | E13: 430 | F13: 430 | G13: 430 | H13: 430 | I13: 430 | J13: 430 | K13: 430 | L13: 430 | M13: 450 | N13: 500
B14: 19年 | C14: 470 | D14: 470 | E14: 420 | F14: 420 | G14: 420 | H14: 420 | I14: 400 | J14: 400 | K14: 380 | L14: 380 | M14: 370 | N14: 370
B15: 20年 | C15: 370 | D15: 370 | E15: 370 | F15: 338 | G15: 338 | H15: 338 | I15: 338 | J15: 338 | K15: 328 | L15: 328 | M15: 358 | N15: 358
B16: 21年 | C16: 358 | D16: 358 | E16: 358 | F16: 408 | G16: 458 | H16: 488 | I16: 508 | J16: 558 | K16: 608 | L16: 608 | M16: 608 | N16: 608
B17: 22年 | C17: 608 | D17: 608 | E17: 608 | F17: 645.6 | G17: 745.6 | H17: 858 | I17: 958 | J17: 958
A18: 北方煤（兰花） | B18: 18年 | C18: 964 | D18: 984 | E18: 984 | F18: 964 | G18: 914 | H18: 911 | I18: 911 | J18: 901 | K18: 896 | L18: 974 | M18: 974 | N18: 967
B19: 19年 | C19: 917 | D19: 917 | E19: 903.67 | F19: 886 | G19: 876 | H19: 866 | I19: 839 | J19: 802.53 | K19: 802.53 | L19: 802.53 | M19: 752.53 | N19: 752.5
B20: 20年 | C20: 752.33 | D20: 772.33 | E20: 772.33 | F20: 732.33 | G20: 702.33 | H20: 755.67 | I20: 755.67 | J20: 692.66667 | K20: 692.66667 | L20: 769.33333 | M20: 823 | N20: 902.66667
B21: 21年 | C21: 1003 | D21: 1003 | E21: 859 | F21: 956 | G21: 1125 | H21: 1125 | I21: 1203 | J21: 1388 | K21: 1588 | L21: 2309 | M21: 1489 | N21: 1416
B22: 22年 | C22: 1564.7616 | D22: 1707.3545 | E22: 1531.4466 | F22: 1631.9322 | G22: 1574.0976 | H22: 1554.3867 | I22: 1491 | J22: 1443

Sheet 打印-走势图（4张17-21)
A1: 二铵、硫磺、磷矿、北方煤价格走势（18年-22年）
A2: 品种 | B2: 年份 | C2: 1月 | D2: 2月 | E2: 3月 | F2: 4月 | G2: 5月 | H2: 6月 | I2: 7月 | J2: 8月 | K2: 9月 | L2: 10月 | M2: 11月 | N2: 12月
A3: 二铵 | B3: 17年 | C3: 2134.8937 | D3: 2300.4024 | E3: 2353.5189 | F3: 2376.9914 | G3: 2370.111 | H3: 2285.1173 | I3: 2235.389 | J3: 2225.4675 | K3: 2229.8995 | L3: 2235.7325 | M3: 2329.2131 | N3: 2470.3062
B4: 18年 | C4: 2501.2773 | D4: 2526.6649 | E4: 2597.1353 | F4: 2548.6285 | G4: 2565.6194 | H4: 2575.9278 | I4: 2678.8684 | J4: 2733.1973 | K4: 2745.262 | L4: 2742.6343 | M4: 2700 | N4: 2700
B5: 19年 | C5: 2614 | D5: 2625 | E5: 2520.3918 | F5: 2512.1307 | G5: 2429.0092 | H5: 2407.3258 | I5: 2214.2749 | J5: 2214.1737 | K5: 2187.0372 | L5: 2139.2073 | M5: 2103.8387 | N5: 2061.2315
B6: 20年 | C6: 2085.8565 | D6: 1986.9905 | E6: 1986.9905 | F6: 2071.5497 | G6: 2060.8699 | H6: 2071.9194 | I6: 2098.8153 | J6: 2082.682 | K6: 2176.0454 | L6: 2238.3727 | M6: 2273.7149 | N6: 2310.9231
B7: 21年 | C7: 2365.1228 | D7: 2471.1848 | E7: 2727.3676 | F7: 3293.7439 | G7: 3225.7658 | H7: 3262.175 | I7: 3373.0201 | J7: 3508.2873 | K7: 3780.2887 | L7: 3742.6374 | M7: 3536.1539 | N7: 3536.0994
A8: 硫磺 | B8: 17年 | C8: 917 | D8: 937 | E8: 923 | F8: 833 | G8: 843 | H8: 867 | I8: 932 | J8: 1013 | K8: 1075 | L8: 1416 | M8: 1632 | N8: 1331
B9: 18年 | C9: 1214 | D9: 1229 | E9: 1147 | F9: 1089 | G9: 1157 | H9: 1178 | I9: 1223 | J9: 1358 | K9: 1517 | L9: 1489 | M9: 1428 | N9: 1260.5
B10: 19年 | C10: 1163.57 | D10: 1116 | E10: 1035.9 | F10: 1027.73 | G10: 1002.8571 | H10: 993.68421 | I10: 871.08696 | J10: 782.27273 | K10: 672.6 | L10: 632.36842 | M10: 553.57143 | N10: 569.09091
B11: 20年 | C11: 626.5625 | D11: 641.13636 | E11: 698.86364 | F11: 628.40909 | G11: 671.05263 | H11: 691.19048 | I11: 660.86957 | J11: 681.90476 | K11: 732.17391 | L11: 776.17647 | M11: 836.36364 | N11: 950.47619
B12: 21年 | C12: 1122.75 | D12: 1468.2353 | E12: 1379.5652 | F12: 1450 | G12: 1584.4737 | H12: 1627.8571 | I12: 1614.3182 | J12: 1804.0909 | K12: 1938.4091 | L12: 1967.0588 | M12: 2031.8182 | N12: 2343.0435
A13: 磷矿 | B13: 17年 | C13: 340 | D13: 355 | E13: 355 | F13: 355 | G13: 355 | H13: 355 | I13: 355 | J13: 355 | K13: 355 | L13: 355 | M13: 355 | N13: 430
B14: 18年 | C14: 430 | D14: 430 | E14: 430 | F14: 430 | G14: 430 | H14: 430 | I14: 430 | J14: 430 | K14: 430 | L14: 430 | M14: 450 | N14: 500
B15: 19年 | C15: 470 | D15: 470 | E15: 420 | F15: 420 | G15: 420 | H15: 420 | I15: 400 | J15: 400 | K15: 380 | L15: 380 | M15: 370 | N15: 370
B16: 20年 | C16: 370 | D16: 370 | E16: 370 | F16: 338 | G16: 338 | H16: 338 | I16: 338 | J16: 338 | K16: 328 | L16: 328 | M16: 358 | N16: 358
B17: 21年 | C17: 358 | D17: 358 | E17: 358 | F17: 408 | G17: 458 | H17: 488 | I17: 508 | J17: 558 | K17: 608 | L17: 608 | M17: 608 | N17: 608
A18: 北方煤（兰花）

Sheet 走势图 (近5年3张)
A1: 日期 | B1: 14年1月 | C1: 14年2月 | D1: 14年3月 | E1: 14年4月 | F1: 14年5月 | G1: 14年6月 | H1: 14年7月 | I1: 14年8月 | J1: 14年9月 | K1: 14年10月 | L1: 14年11月 | M1: 14年12月 | N1: 15年1月 | O1: 15年2月 | P1: 15年3月 | Q1: 15年4月 | R1: 15年5月 | S1: 15年6月 | T1: 15年7月 | U1: 15年8月 | V1: 15年9月 | W1: 15年10月 | X1: 15年11月 | Y1: 15年12月 | Z1: 16年1月 | AA1: 16年2月 | AB1: 16年3月 | AC1: 16年4月 | AD1: 16年5月 | AE1: 16年6月 | AF1: 16年7月 | AG1: 16年8月 | AH1: 16年9月 | AI1: 16年10月 | AJ1: 16年11月 | AK1: 16年12月 | AL1: 17年1月 | AM1: 17年2月 | AN1: 17年3月 | AO1: 17年4月 | AP1: 17年5月 | AQ1: 17年6月 | AR1: 17年7月 | AS1: 17年8月 | AT1: 17年9月 | AU1: 17年10月 | AV1: 17年11月 | AW1: 17年12月 | AX1: 18年1月 | AY1: 18年2月 | AZ1: 18年3月 | BA1: 18年4月 | BB1: 18年5月 | BC1: 18年6月 | BD1: 18年7月 | BE1: 18年8月 | BF1: 18年9月 | BG1: 18年10月 | BH1: 18年11月 | BI1: 18年12月 | BJ1: 19年1月 | BK1: 19年2月 | BL1: 19年3月 | BM1: 19年4月 | BN1: 19年5月 | BO1: 19年6月 | BP1: 19年7月 | BQ1: 19年8月 | BR1: 19年9月 | BS1: 19年10月 | BT1: 19年11月 | BU1: 19年12月 | BV1: 20年1月 | BW1: 20年2月 | BX1: 20年3月 | BY1: 20年4月 | BZ1: 20年5月 | CA1: 20年6月 | CB1: 20年7月 | CC1: 20年8月 | CD1: 20年9月 | CE1: 20年10月 | CF1: 20年11月 | CG1: 20年12月 | CH1: 21年1月 | CI1: 21年2月 | CJ1: 21年3月 | CK1: 21年4月 | CL1: 21年5月 | CM1: 21年6月 | CN1: 21年7月 | CO1: 21年8月 | CP1: 21年9月 | CQ1: 21年10月 | CR1: 21年11月 | CS1: 21年12月 | CT1: 22年1月 | CU1: 22年2月 | CV1: 22年3月 | CW1: 22年4月 | CX1: 22年5月 | CY1: 22年6月 | CZ1: 22年7月 | DA1: 22年8月 | DF1: 价格预测 | DL1: 下半年价格
A2: 二铵 | B2: 2214.8425 | C2: 2336.528 | D2: 2486.7356 | E2: 2463.6406 | F2: 2421.1606 | G2: 2389.9844 | H2: 2517.102 | I2: 2610.325 | J2: 2740.5815 | K2: 2534.1563 | L2: 2670.6606 | M2: 2577.8185 | N2: 2589.444 | O2: 2675.0397 | P2: 2661.9709 | Q2: 2677.4974 | R2: 2720.9215 | S2: 2716.1916 | T2: 2717.9307 | U2: 2742.6795 | V2: 2730.5512 | W2: 2667.0278 | X2: 2482.1079 | Y2: 2479.7249 | Z2: 2369.1368 | AA2: 2389.9206 | AB2: 2353.8078 | AC2: 2228.7594 | AD2: 2057.6541 | AE2: 2037.7391 | AF2: 2060.6494 | AG2: 2102.8897 | AH2: 2033.4587 | AI2: 1899.7562 | AJ2: 1955.911 | AK2: 1983.9083 | AL2: 2134.8937 | AM2: 2300.4024 | AN2: 2353.5189 | AO2: 2376.9914 | AP2: 2370.111 | AQ2: 2285.1173 | AR2: 2235.389 | AS2: 2225.4675 | AT2: 2229.8995 | AU2: 2235.7325 | AV2: 2329.2131 | AW2: 2470.3062 | AX2: 2501.2773 | AY2: 2526.6649 | AZ2: 2597.1353 | BA2: 2548.6285 | BB2: 2565.6194 | BC2: 2575.9278 | BD2: 2678.8684 | BE2: 2733.1973 | BF2: 2745.262 | BG2: 2742.6343 | BH2: 2700 | BI2: 2700 | BJ2: 2614 | BK2: 2625 | BL2: 2520.3918 | BM2: 2512.1307 | BN2: 2429.0092 | BO2: 2407.3258 | BP2: 2214.2749 | BQ2: 2214.1737 | BR2: 2187.0372 | BS2: 2139.2073 | BT2: 2103.8387 | BU2: 2061.2315 | BV2: 2085.8565 | BW2: 1986.9905 | BX2: 1986.9905 | BY2: 2071.5497 | BZ2: 2060.8699 | CA2: 2071.9194 | CB2: 2098.8153 | CC2: 2082.682 | CD2: 2176.0454 | CE2: 2238.3727 | CF2: 2273.7149 | CG2: 2310.9231 | CH2: 2365.1228 | CI2: 2471.1848 | CJ2: 2727.3676 | CK2: 3293.7439 | CL2: 3225.7658 | CM2: 3262.175 | CN2: 3373.0201 | CO2: 3508.2873 | CP2: 3780.2887 | CQ2: 3742.6374 | CR2: 3536.1539 | CS2: 3536.0994 | CT2: 3635.9425 | CU2: 3566.1321 | CV2: 4271.2606 | CW2: 4362 | CX2: 5029 | CY2: 5280 | CZ2: 5705 | DA2: 5154 | DL2: =(5900*22+4000*63)/85 -> 4491.7647 | DM2: =(5900*22+4000*63)/85 -> 4491.7647 | DN2: =(5900*22+4000*63)/85 -> 4491.7647 | DO2: =AVERAGE(B2:CZ2) -> 2627.2233 | DP2: =MAX(B2:CZ2) -> 5705 | DQ2: =MIN(B2:CZ2) -> 1899.7562
A3: 二铵
A4: 硫磺到厂 | B4: 1327 | C4: 1491 | D4: 1408 | E4: 1104 | F4: 1307 | G4: 1315 | H4: 1361 | I4: 1291 | J4: 1197 | K4: 1024 | L4: 1145 | M4: 1314 | N4: 1372 | O4: 1354 | P4: 1370 | Q4: 1171 | R4: 1168 | S4: 1250 | T4: 1268 | U4: 1201 | V4: 1063 | W4: 1048 | X4: 1140 | Y4: 1080 | Z4: 945 | AA4: 841 | AB4: 760 | AC4: 767 | AD4: 753 | AE4: 711 | AF4: 669 | AG4: 689 | AH4: 729 | AI4: 763 | AJ4: 870 | AK4: 897 | AL4: 887 | AM4: 907 | AN4: 893 | AO4: 803 | AP4: 813 | AQ4: 837 | AR4: 902 | AS4: 983 | AT4: 1045 | AU4: 1386 | AV4: 1602 | AW4: 1301 | AX4: =AX19+30 -> 1214 | AY4: =AY19+30 -> 1229 | AZ4: =AZ19+30 -> 1147 | BA4: =BA19+30 -> 1089 | BB4: =BB19+30 -> 1157 | BC4: =BC19+30 -> 1178 | BD4: =BD19+30 -> 1223 | BE4: =BE19+30 -> 1358 | ... DA4: =DA19+30 -> 1086.5217 | DO4: =AVERAGE(B4:CZ4) -> 1238.6648 | DP4: =MAX(B4:CZ4) -> 4064 | DQ4: =MIN(B4:CZ4) -> 553.57143
A5: 长江港硫磺现货价 | DL5: =DL2/DO7 -> 1925.7867 | DM5: =DM2/DP7 -> 1181.8932 | DN5: =DN2/DQ7 -> 3645.8015
A6: 长江港硫磺现货价
A7: 二铵/硫磺 | B7: =B2/B4 -> 1.6690599 | C7: =C2/C4 -> 1.5670879 | D7: =D2/D4 -> 1.7661475 | E7: =E2/E4 -> 2.2315586 | F7: =F2/F4 -> 1.8524565 | G7: =G2/G4 -> 1.8174786 | H7: =H2/H4 -> 1.8494504 | I7: =I2/I4 -> 2.0219403 | ... DA7: =DA2/DA4 -> 4.7435774 | DL7: =DL2/DL5 -> 2.3324311 | DM7: =DM2/DM5 -> 3.8004829 | DN7: =DN2/DN5 -> 1.2320377 | DO7: =AVERAGE(B7:CZ7) -> 2.3324311 | DP7: =MAX(B7:CZ7) -> 3.8004829 | DQ7: =MIN(B7:CZ7) -> 1.2320377
A8: 二铵 | B8: 2214.8425 | C8: 2336.528 | D8: 2486.7356 | E8: 2463.6406 | F8: 2421.1606 | G8: 2389.9844 | H8: 2517.102 | I8: 2610.325 | J8: 2740.5815 | K8: 2534.1563 | L8: 2670.6606 | M8: 2577.8185 | N8: 2589.444 | O8: 2675.0397 | P8: 2661.9709 | Q8: 2677.4974 | R8: 2720.9215 | S8: 2716.1916 | T8: 2717.9307 | U8: 2742.6795 | V8: 2730.5512 | W8: 2667.0278 | X8: 2482.1079 | Y8: 2479.7249 | Z8: 2369.1368 | AA8: 2389.9206 | AB8: 2353.8078 | AC8: 2228.7594 | AD8: 2057.6541 | AE8: 2037.7391 | AF8: 2060.6494 | AG8: 2102.8897 | AH8: 2033.4587 | AI8: 1899.7562 | AJ8: 1955.911 | AK8: 1983.9083 | AL8: 2134.8937 | AM8: 2300.4024 | AN8: 2353.5189 | AO8: 2376.9914 | AP8: 2370.111 | AQ8: 2285.1173 | AR8: 2235.389 | AS8: 2225.4675 | AT8: 2229.8995 | AU8: 2235.7325 | AV8: 2329.2131 | AW8: 2470.3062 | AX8: 2501.2773 | AY8: 2526.6649 | AZ8: 2597.1353 | BA8: 2548.6285 | BB8: 2565.6194 | BC8: 2575.9278 | BD8: 2678.8684 | BE8: 2733.1973 | BF8: 2745.262 | BG8: 2742.6343 | BH8: 2700 | BI8: 2700 | BJ8: 2614 | BK8: 2625 | BL8: 2520.3918 | BM8: 2512.1307 | BN8: 2429.0092 | BO8: 2407.3258 | BP8: 2214.2749 | BQ8: 2214.1737 | BR8: 2187.0372 | BS8: 2139.2073 | BT8: 2103.8387 | BU8: 2061.2315 | BV8: 2085.8565 | BW8: 1986.9905 | BX8: 1986.9905 | BY8: 2071.5497 | BZ8: 2060.8699 | CA8: 2071.9194 | CB8: 2098.8153 | CC8: 2082.682 | CD8: 2176.0454 | CE8: 2238.3727 | CF8: 2273.7149 | CG8: 2310.9231 | CH8: 2365.1228 | CI8: 2471.1848 | CJ8: 2727.3676 | CK8: 3293.7439 | CL8: 3225.7658 | CM8: 3262.175 | CN8: 3373.0201 | CO8: 3508.2873 | CP8: 3780.2887 | CQ8: 3742.6374 | CR8: 3536.1539 | CS8: 3536.0994 | CT8: 3635.9425 | CU8: 3566.1321 | CV8: 4271.2606 | CW8: 4362 | CX8: 5029 | CY8: 5280 | CZ8: 5705 | DA8: 5154 | DL8: =DL2 -> 4491.7647 | DM8: =DM2 -> 4491.7647 | DN8: =DN2 -> 4491.7647 | DO8: =AVERAGE(B8:CZ8) -> 2627.2233 | DP8: =MAX(B8:CZ8) -> 5705 | DQ8: =MIN(B8:CZ8) -> 1899.7562
A9: 股份27%磷矿 | B9: 400 | C9: 400 | D9: 400 | E9: 380 | F9: 380 | G9: 380 | H9: 380 | I9: 380 | J9: 380 | K9: 380 | L9: 380 | M9: 380 | N9: 390 | O9: 390 | P9: 380 | Q9: 380 | R9: 380 | S9: 380 | T9: 380 | U9: 370 | V9: 370 | W9: 370 | X9: 370 | Y9: 370 | Z9: 350 | AA9: 350 | AB9: 350 | AC9: 350 | AD9: 350 | AE9: 350 | AF9: 350 | AG9: 340 | AH9: 340 | AI9: 340 | AJ9: 340 | AK9: 340 | AL9: 340 | AM9: 355 | AN9: 355 | AO9: 355 | AP9: 355 | AQ9: 355 | AR9: 355 | AS9: 355 | AT9: 355 | AU9: 355 | AV9: 355 | AW9: 430 | AX9: 430 | AY9: 430 | AZ9: 430 | BA9: 430 | BB9: 430 | BC9: 430 | BD9: 430 | BE9: 430 | BF9: 430 | BG9: 430 | BH9: 450 | BI9: 500 | BJ9: 470 | BK9: 470 | BL9: 420 | BM9: 420 | BN9: 420 | BO9: 420 | BP9: 400 | BQ9: 400 | BR9: 380 | BS9: 380 | BT9: 370 | BU9: 370 | BV9: 370 | BW9: 370 | BX9: 370 | BY9: 338 | BZ9: 338 | CA9: 338 | CB9: 338 | CC9: 338 | CD9: 328 | CE9: 328 | CF9: 358 | CG9: 358 | CH9: 358 | CI9: 358 | CJ9: 358 | CK9: 408 | CL9: 458 | CM9: 488 | CN9: 508 | CO9: 558 | CP9: 608 | CQ9: 608 | CR9: 608 | CS9: 608 | CT9: 608 | CU9: 608 | CV9: 608 | CW9: 645.6 | CX9: 745.6 | CY9: 858 | CZ9: 958 | DA9: 958 | DL9: =DL8/DO12 -> 710.62369 | DM9: =DL8/DP12 -> 556.40027 | DN9: =DL8/DQ12 -> 836.41716 | DO9: =AVERAGE(B9:CZ9) -> 416.69126 | DP9: =MAX(B9:CZ9) -> 958 | DQ9: =MIN(B9:CZ9) -> 328
A10: 股份27%磷矿
A11: 股份27%磷矿
A12: 二铵/磷矿 | B12: =B8/B9 -> 5.5371063 | C12: =C8/C9 -> 5.8413201 | D12: =D8/D9 -> 6.216839 | E12: =E8/E9 -> 6.4832649 | F12: =F8/F9 -> 6.3714752 | G12: =G8/G9 -> 6.2894327 | H12: =H8/H9 -> 6.6239527 | I12: =I8/I9 -> 6.8692762 | ... DA12: =DA8/DA9 -> 5.3799582 | DL12: =DL8/DL9 -> 6.3208767 | DM12: =DM8/DM9 -> 8.0729017 | DN12: =DN8/DN9 -> 5.3702446 | DO12: =AVERAGE(B12:CZ12) -> 6.3208767 | DP12: =MAX(B12:CZ12) -> 8.0729017 | DQ12: =MIN(B12:CZ12) -> 5.3702446
A13: 二铵 | B13: 2214.8425 | C13: 2336.528 | D13: 2486.7356 | E13: 2463.6406 | F13: 2421.1606 | G13: 2389.9844 | H13: 2517.102 | I13: 2610.325 | J13: 2740.5815 | K13: 2534.1563 | L13: 2670.6606 | M13: 2577.8185 | N13: 2589.444 | O13: 2675.0397 | P13: 2661.9709 | Q13: 2677.4974 | R13: 2720.9215 | S13: 2716.1916 | T13: 2717.9307 | U13: 2742.6795 | V13: 2730.5512 | W13: 2667.0278 | X13: 2482.1079 | Y13: 2479.7249 | Z13: 2369.1368 | AA13: 2389.9206 | AB13: 2353.8078 | AC13: 2228.7594 | AD13: 2057.6541 | AE13: 2037.7391 | AF13: 2060.6494 | AG13: 2102.8897 | AH13: 2033.4587 | AI13: 1899.7562 | AJ13: 1955.911 | AK13: 1983.9083 | AL13: 2134.8937 | AM13: 2300.4024 | AN13: 2353.5189 | AO13: 2376.9914 | AP13: 2370.111 | AQ13: 2285.1173 | AR13: 2235.389 | AS13: 2225.4675 | AT13: 2229.8995 | AU13: 2235.7325 | AV13: 2329.2131 | AW13: 2470.3062 | AX13: 2501.2773 | AY13: 2526.6649 | AZ13: 2597.1353 | BA13: 2548.6285 | BB13: 2565.6194 | BC13: 2575.9278 | BD13: 2678.8684 | BE13: 2733.1973 | BF13: 2745.262 | BG13: 2742.6343 | BH13: 2700 | BI13: 2700 | BJ13: 2614 | BK13: 2625 | BL13: 2520.3918 | BM13: 2512.1307 | BN13: 2429.0092 | BO13: 2407.3258 | BP13: 2214.2749 | BQ13: 2214.1737 | BR13: 2187.0372 | BS13: 2139.2073 | BT13: 2103.8387 | BU13: 2061.2315 | BV13: 2085.8565 | BW13: 1986.9905 | BX13: 1986.9905 | BY13: 2071.5497 | BZ13: 2060.8699 | CA13: 2071.9194 | CB13: 2098.8153 | CC13: 2082.682 | CD13: 2176.0454 | CE13: 2238.3727 | CF13: 2273.7149 | CG13: 2310.9231 | CH13: 2365.1228 | CI13: 2471.1848 | CJ13: 2727.3676 | CK13: 3293.7439 | CL13: 3225.7658 | CM13: 3262.175 | CN13: 3373.0201 | CO13: 3508.2873 | CP13: 3780.2887 | CQ13: 3742.6374 | CR13: 3536.1539 | CS13: 3536.0994 | CT13: 3635.9425 | CU13: 3566.1321 | CV13: 4271.2606 | CW13: 4362 | CX13: 5029 | CY13: 5280 | CZ13: 5705 | DA13: 5154 | DL13: =DL7 -> 2.3324311 | DM13: =DM7 -> 3.8004829 | DN13: =DN7 -> 1.2320377 | DO13: =AVERAGE(B13:CZ13) -> 2627.2233 | DP13: =MAX(B13:CZ13) -> 5705 | DQ13: =MIN(B13:CZ13) -> 1899.7562
A14: 北方煤（兰花） | AX14: 964 | AY14: 984 | AZ14: 984 | BA14: 964 | BB14: 914 | BC14: 911 | BD14: 911 | BE14: 901 | BF14: 896 | BG14: 974 | BH14: 974 | BI14: 967 | BJ14: 917 | BK14: 917 | BL14: 903.67 | BM14: 886 | BN14: 876 | BO14: 866 | BP14: 839 | BQ14: 802.53 | BR14: 802.53 | BS14: 802.53 | BT14: 752.53 | BU14: 752.5 | BV14: 752.33 | BW14: 772.33 | BX14: 772.33 | BY14: 732.33 | BZ14: 702.33 | CA14: 755.67 | CB14: 755.67 | CC14: 692.66667 | CD14: 692.66667 | CE14: 769.33333 | CF14: 823 | CG14: 902.66667 | CH14: 1003 | CI14: 1003 | CJ14: 859 | CK14: 956 | CL14: 1125 | CM14: 1125 | CN14: 1203 | CO14: 1388 | CP14: 1588 | CQ14: 2309 | CR14: 1489 | CS14: 1416 | CT14: 1564.7616 | CU14: 1707.3545 | CV14: 1531.4466 | CW14: 1631.9322 | CX14: 1574.0976 | CY14: 1554.3867 | CZ14: 1491 | DA14: 1443 | DL14: =DL13/DO17 -> #DIV/0! | DM14: =DL13/DP17 -> #DIV/0! | DN14: =DL13/DQ17 -> #DIV/0! | DO14: =AVERAGE(B14:CZ14) -> 1038.2471 | DP14: =MAX(B14:CZ14) -> 2309 | DQ14: =MIN(B14:CZ14) -> 692.66667
A15: 北方煤（兰花）
A16: 北方煤（兰花）
A17: 二铵/北方煤 | B17: =B13/B14 -> #DIV/0! | C17: =C13/C14 -> #DIV/0! | D17: =D13/D14 -> #DIV/0! | E17: =E13/E14 -> #DIV/0! | F17: =F13/F14 -> #DIV/0! | G17: =G13/G14 -> #DIV/0! | H17: =H13/H14 -> #DIV/0! | I17: =I13/I14 -> #DIV/0! | ... DA17: =DA13/DA14 -> 3.5717256 | DL17: =DL13/DL14 -> #DIV/0! | DM17: =DM13/DM14 -> #DIV/0! | DN17: =DN13/DN14 -> #DIV/0! | DO17: =AVERAGE(B17:CZ17) -> #DIV/0! | DP17: =MAX(B17:CZ17) -> #DIV/0! | DQ17: =MIN(B17:CZ17) -> #DIV/0!
DL18: 4、紧盯历史价格规律： 二铵、硫磺、磷矿石14-22年历史价格 （1）二铵均价2621、最高价5280（22年6月）、最低价1900（16年10月）。 （2）硫磺港口现货均价1224、最高价4034（22年5月）、最低价524（19年11月）。 （3）27%磷矿石均价417、最高价958（22年7月）、最低价328（20年9、10月）。 二铵与硫磺、磷矿14-22年历史价格比值 （1）二铵与硫磺价格平均比值2.368，最高比值4.018（19年11月）、最低比值1.243（22年4月）。 （2）二铵与磷矿价格平均比值6.314，最高比值8.073（19年11月）、最低比值5.297（22年7月）。 按二铵下半年预测均价4492，参照二铵与硫磺、磷矿历史价格比值对硫磺及磷矿石下半年均价测算： （1）硫磺：按平均比值测算为1897、按最高比值测算为1118、按最低比值测算为3615。 （2）27%磷矿石：按平均比值测算为711、按最高比值测算为556、按最低比值测算为836。 故对比当前硫磺、磷矿价格： （1）硫磺当前价2000，下半年达到平均比值需降价103，达到最高比值需降价882。 （2）27%磷矿石当前价958，下半年达到平均比值需降价247，达到最高比值需降价401。
A19: 长江港硫磺现货价 | AX19: 1184 | AY19: 1199 | AZ19: 1117 | BA19: 1059 | BB19: 1127 | BC19: 1148 | BD19: 1193 | BE19: 1328 | BF19: 1487 | BG19: 1459 | BH19: 1398 | BI19: 1230.5 | BJ19: 1133.57 | BK19: 1086 | BL19: 1005.9 | BM19: 997.73 | BN19: 972.85714 | BO19: 963.68421 | BP19: 841.08696 | BQ19: 752.27273 | BR19: 642.6 | BS19: 602.36842 | BT19: 523.57143 | BU19: 539.09091 | BV19: 596.5625 | BW19: 611.13636 | BX19: 668.86364 | BY19: 598.40909 | BZ19: 641.05263 | CA19: 661.19048 | CB19: 630.86957 | CC19: 651.90476 | CD19: 702.17391 | CE19: 746.17647 | CF19: 806.36364 | CG19: 920.47619 | CH19: 1092.75 | CI19: 1438.2353 | CJ19: 1349.5652 | CK19: 1420 | CL19: 1554.4737 | CM19: 1597.8571 | CN19: 1584.3182 | CO19: 1774.0909 | CP19: 1908.4091 | CQ19: 1937.0588 | CR19: 2001.8182 | CS19: 2313.0435 | CT19: 2461.25 | CU19: 2569.3333 | CV19: 3236 | CW19: 3510.4762 | CX19: 4034 | CY19: 3538.0952 | CZ19: 1864.2857 | DA19: 1056.5217
A35: =DL18 -> 4、紧盯历史价格规律： 二铵、硫磺、磷矿石14-22年历史价格 （1）二铵均价2621、最高价5280（22年6月）、最低价1900（16年10月）。 （2）硫磺港口现货均价1224、最高价4034（22年5月）、最低价524（19年11月）。 （3）27%磷矿石均价417、最高价958（22年7月）、最低价328（20年9、10月）。 二铵与硫磺、磷矿14-22年历史价格比值 （1）二铵与硫磺价格平均比值2.368，最高比值4.018（19年11月）、最低比值1.243（22年4月）。 （2）二铵与磷矿价格平均比值6.314，最高比值8.073（19年11月）、最低比值5.297（22年7月）。 按二铵下半年预测均价4492，参照二铵与硫磺、磷矿历史价格比值对硫磺及磷矿石下半年均价测算： （1）硫磺：按平均比值测算为1897、按最高比值测算为1118、按最低比值测算为3615。 （2）27%磷矿石：按平均比值测算为711、按最高比值测算为556、按最低比值测算为836。 故对比当前硫磺、磷矿价格： （1）硫磺当前价2000，下半年达到平均比值需降价103，达到最高比值需降价882。 （2）27%磷矿石当前价958，下半年达到平均比值需降价247，达到最高比值需降价401。

Sheet 走势图 (近5年1张)
A1: 日期 | B1: 14年1月 | C1: 14年2月 | D1: 14年3月 | E1: 14年4月 | F1: 14年5月 | G1: 14年6月 | H1: 14年7月 | I1: 14年8月 | J1: 14年9月 | K1: 14年10月 | L1: 14年11月 | M1: 14年12月 | N1: 15年1月 | O1: 15年2月 | P1: 15年3月 | Q1: 15年4月 | R1: 15年5月 | S1: 15年6月 | T1: 15年7月 | U1: 15年8月 | V1: 15年9月 | W1: 15年10月 | X1: 15年11月 | Y1: 15年12月 | Z1: 16年1月 | AA1: 16年2月 | AB1: 16年3月 | AC1: 16年4月 | AD1: 16年5月 | AE1: 16年6月 | AF1: 16年7月 | AG1: 16年8月 | AH1: 16年9月 | AI1: 16年10月 | AJ1: 16年11月 | AK1: 16年12月 | AL1: 17年1月 | AM1: 17年2月 | AN1: 17年3月 | AO1: 17年4月 | AP1: 17年5月 | AQ1: 17年6月 | AR1: 17年7月 | AS1: 17年8月 | AT1: 17年9月 | AU1: 17年10月 | AV1: 17年11月 | AW1: 17年12月 | AX1: 18年1月 | AY1: 18年2月 | AZ1: 18年3月 | BA1: 18年4月 | BB1: 18年5月 | BC1: 18年6月 | BD1: 18年7月 | BE1: 18年8月 | BF1: 18年9月 | BG1: 18年10月 | BH1: 18年11月 | BI1: 18年12月 | BJ1: 19年1月 | BK1: 19年2月 | BL1: 19年3月 | BM1: 19年4月 | BN1: 19年5月 | BO1: 19年6月 | BP1: 19年7月 | BQ1: 19年8月 | BR1: 19年9月 | BS1: 19年10月 | BT1: 19年11月 | BU1: 19年12月 | BV1: 20年1月 | BW1: 20年2月 | BX1: 20年3月 | BY1: 20年4月 | BZ1: 20年5月 | CA1: 20年6月 | CB1: 20年7月 | CC1: 20年8月 | CD1: 20年9月 | CE1: 20年10月 | CF1: 20年11月 | CG1: 20年12月 | CH1: 21年1月 | CI1: 21年2月 | CJ1: 21年3月 | CK1: 21年4月 | CL1: 21年5月 | CM1: 21年6月 | CN1: 21年7月 | CO1: 21年8月 | CP1: 21年9月 | CQ1: 21年10月 | CR1: 21年11月 | CS1: 21年12月 | CT1: 22年1月 | CU1: 22年2月 | CV1: 22年3月 | CW1: 22年4月 | CX1: 22年5月 | CY1: 22年6月 | CZ1: 22年7月 | DA1: 22年8月
A2: 二铵 | B2: 2214.8425 | C2: 2336.528 | D2: 2486.7356 | E2: 2463.6406 | F2: 2421.1606 | G2: 2389.9844 | H2: 2517.102 | I2: 2610.325 | J2: 2740.5815 | K2: 2534.1563 | L2: 2670.6606 | M2: 2577.8185 | N2: 2589.444 | O2: 2675.0397 | P2: 2661.9709 | Q2: 2677.4974 | R2: 2720.9215 | S2: 2716.1916 | T2: 2717.9307 | U2: 2742.6795 | V2: 2730.5512 | W2: 2667.0278 | X2: 2482.1079 | Y2: 2479.7249 | Z2: 2369.1368 | AA2: 2389.9206 | AB2: 2353.8078 | AC2: 2228.7594 | AD2: 2057.6541 | AE2: 2037.7391 | AF2: 2060.6494 | AG2: 2102.8897 | AH2: 2033.4587 | AI2: 1899.7562 | AJ2: 1955.911 | AK2: 1983.9083 | AL2: 2134.8937 | AM2: 2300.4024 | AN2: 2353.5189 | AO2: 2376.9914 | AP2: 2370.111 | AQ2: 2285.1173 | AR2: 2235.389 | AS2: 2225.4675 | AT2: 2229.8995 | AU2: 2235.7325 | AV2: 2329.2131 | AW2: 2470.3062 | AX2: 2501.2773 | AY2: 2526.6649 | AZ2: 2597.1353 | BA2: 2548.6285 | BB2: 2565.6194 | BC2: 2575.9278 | BD2: 2678.8684 | BE2: 2733.1973 | BF2: 2745.262 | BG2: 2742.6343 | BH2: 2700 | BI2: 2700 | BJ2: 2614 | BK2: 2625 | BL2: 2520.3918 | BM2: 2512.1307 | BN2: 2429.0092 | BO2: 2407.3258 | BP2: 2214.2749 | BQ2: 2214.1737 | BR2: 2187.0372 | BS2: 2139.2073 | BT2: 2103.8387 | BU2: 2061.2315 | BV2: 2085.8565 | BW2: 1986.9905 | BX2: 1986.9905 | BY2: 2071.5497 | BZ2: 2060.8699 | CA2: 2071.9194 | CB2: 2098.8153 | CC2: 2082.682 | CD2: 2176.0454 | CE2: 2238.3727 | CF2: 2273.7149 | CG2: 2310.9231 | CH2: 2365.1228 | CI2: 2471.1848 | CJ2: 2727.3676 | CK2: 3293.7439 | CL2: 3225.7658 | CM2: 3262.175 | CN2: 3373.0201 | CO2: 3508.2873 | CP2: 3780.2887 | CQ2: 3742.6374 | CR2: 3536.1539 | CS2: 3536.0994 | CT2: 3635.9425 | CU2: 3566.1321 | CV2: 4271.2606 | CW2: 4362 | CX2: 5029 | CY2: 5280 | CZ2: 5705 | DA2: 5460
A3: 二铵 | CZ3: 5074.3294 | DA3: 4400
A4: 长江港硫磺现货价 | B4: 1327 | C4: 1491 | D4: 1408 | E4: 1104 | F4: 1307 | G4: 1315 | H4: 1361 | I4: 1291 | J4: 1197 | K4: 1024 | L4: 1145 | M4: 1314 | N4: 1372 | O4: 1354 | P4: 1370 | Q4: 1171 | R4: 1168 | S4: 1250 | T4: 1268 | U4: 1201 | V4: 1063 | W4: 1048 | X4: 1140 | Y4: 1080 | Z4: 945 | AA4: 841 | AB4: 760 | AC4: 767 | AD4: 753 | AE4: 711 | AF4: 669 | AG4: 689 | AH4: 729 | AI4: 763 | AJ4: 870 | AK4: 897 | AL4: 887 | AM4: 907 | AN4: 893 | AO4: 803 | AP4: 813 | AQ4: 837 | AR4: 902 | AS4: 983 | AT4: 1045 | AU4: 1386 | AV4: 1602 | AW4: 1301 | AX4: 1184 | AY4: 1199 | AZ4: 1117 | BA4: 1059 | BB4: 1127 | BC4: 1148 | BD4: 1193 | BE4: 1328 | BF4: 1487 | BG4: 1459 | BH4: 1398 | BI4: 1230.5 | BJ4: 1133.57 | BK4: 1086 | BL4: 1005.9 | BM4: 997.73 | BN4: 972.85714 | BO4: 963.68421 | BP4: 841.08696 | BQ4: 752.27273 | BR4: 642.6 | BS4: 602.36842 | BT4: 523.57143 | BU4: 539.09091 | BV4: 596.5625 | BW4: 611.13636 | BX4: 668.86364 | BY4: 598.40909 | BZ4: 641.05263 | CA4: 661.19048 | CB4: 630.86957 | CC4: 651.90476 | CD4: 702.17391 | CE4: 746.17647 | CF4: 806.36364 | CG4: 920.47619 | CH4: 1092.75 | CI4: 1438.2353 | CJ4: 1349.5652 | CK4: 1420 | CL4: 1554.4737 | CM4: 1597.8571 | CN4: 1584.3182 | CO4: 1774.0909 | CP4: 1908.4091 | CQ4: 1937.0588 | CR4: 2001.8182 | CS4: 2313.0435 | CT4: 2461.25 | CU4: 2569.3333 | CV4: 3236 | CW4: 3510.4762 | CX4: 4034 | CY4: 3538.0952 | CZ4: 1864.2857 | DA4: 1056.5217
A5: 长江港硫磺现货价 | CZ5: 2000 | DA5: 1900
A6: 长江港硫磺现货价 | CZ6: 2000 | DA6: 1200
A7: 二铵/硫磺 | B7: =B2/B4 -> 1.6690599 | C7: =C2/C4 -> 1.5670879 | D7: =D2/D4 -> 1.7661475 | E7: =E2/E4 -> 2.2315586 | F7: =F2/F4 -> 1.8524565 | G7: =G2/G4 -> 1.8174786 | H7: =H2/H4 -> 1.8494504 | I7: =I2/I4 -> 2.0219403 | ... CZ7: =CZ2/CZ4 -> 3.0601533
A8: 二铵 | B8: 2214.8425 | C8: 2336.528 | D8: 2486.7356 | E8: 2463.6406 | F8: 2421.1606 | G8: 2389.9844 | H8: 2517.102 | I8: 2610.325 | J8: 2740.5815 | K8: 2534.1563 | L8: 2670.6606 | M8: 2577.8185 | N8: 2589.444 | O8: 2675.0397 | P8: 2661.9709 | Q8: 2677.4974 | R8: 2720.9215 | S8: 2716.1916 | T8: 2717.9307 | U8: 2742.6795 | V8: 2730.5512 | W8: 2667.0278 | X8: 2482.1079 | Y8: 2479.7249 | Z8: 2369.1368 | AA8: 2389.9206 | AB8: 2353.8078 | AC8: 2228.7594 | AD8: 2057.6541 | AE8: 2037.7391 | AF8: 2060.6494 | AG8: 2102.8897 | AH8: 2033.4587 | AI8: 1899.7562 | AJ8: 1955.911 | AK8: 1983.9083 | AL8: 2134.8937 | AM8: 2300.4024 | AN8: 2353.5189 | AO8: 2376.9914 | AP8: 2370.111 | AQ8: 2285.1173 | AR8: 2235.389 | AS8: 2225.4675 | AT8: 2229.8995 | AU8: 2235.7325 | AV8: 2329.2131 | AW8: 2470.3062 | AX8: 2501.2773 | AY8: 2526.6649 | AZ8: 2597.1353 | BA8: 2548.6285 | BB8: 2565.6194 | BC8: 2575.9278 | BD8: 2678.8684 | BE8: 2733.1973 | BF8: 2745.262 | BG8: 2742.6343 | BH8: 2700 | BI8: 2700 | BJ8: 2614 | BK8: 2625 | BL8: 2520.3918 | BM8: 2512.1307 | BN8: 2429.0092 | BO8: 2407.3258 | BP8: 2214.2749 | BQ8: 2214.1737 | BR8: 2187.0372 | BS8: 2139.2073 | BT8: 2103.8387 | BU8: 2061.2315 | BV8: 2085.8565 | BW8: 1986.9905 | BX8: 1986.9905 | BY8: 2071.5497 | BZ8: 2060.8699 | CA8: 2071.9194 | CB8: 2098.8153 | CC8: 2082.682 | CD8: 2176.0454 | CE8: 2238.3727 | CF8: 2273.7149 | CG8: 2310.9231 | CH8: 2365.1228 | CI8: 2471.1848 | CJ8: 2727.3676 | CK8: 3293.7439 | CL8: 3225.7658 | CM8: 3262.175 | CN8: 3373.0201 | CO8: 3508.2873 | CP8: 3780.2887 | CQ8: 3742.6374 | CR8: 3536.1539 | CS8: 3536.0994 | CT8: 3635.9425 | CU8: 3566.1321 | CV8: 4271.2606 | CW8: 4362 | CX8: 5029 | CY8: 5280 | CZ8: =(5900*22+4786*63)/85 -> 5074.3294 | DA8: 4400
A9: 股份27%磷矿 | B9: 400 | C9: 400 | D9: 400 | E9: 380 | F9: 380 | G9: 380 | H9: 380 | I9: 380 | J9: 380 | K9: 380 | L9: 380 | M9: 380 | N9: 390 | O9: 390 | P9: 380 | Q9: 380 | R9: 380 | S9: 380 | T9: 380 | U9: 370 | V9: 370 | W9: 370 | X9: 370 | Y9: 370 | Z9: 350 | AA9: 350 | AB9: 350 | AC9: 350 | AD9: 350 | AE9: 350 | AF9: 350 | AG9: 340 | AH9: 340 | AI9: 340 | AJ9: 340 | AK9: 340 | AL9: 340 | AM9: 355 | AN9: 355 | AO9: 355 | AP9: 355 | AQ9: 355 | AR9: 355 | AS9: 355 | AT9: 355 | AU9: 355 | AV9: 355 | AW9: 430 | AX9: 430 | AY9: 430 | AZ9: 430 | BA9: 430 | BB9: 430 | BC9: 430 | BD9: 430 | BE9: 430 | BF9: 430 | BG9: 430 | BH9: 450 | BI9: 500 | BJ9: 470 | BK9: 470 | BL9: 420 | BM9: 420 | BN9: 420 | BO9: 420 | BP9: 400 | BQ9: 400 | BR9: 380 | BS9: 380 | BT9: 370 | BU9: 370 | BV9: 370 | BW9: 370 | BX9: 370 | BY9: 338 | BZ9: 338 | CA9: 338 | CB9: 338 | CC9: 338 | CD9: 328 | CE9: 328 | CF9: 358 | CG9: 358 | CH9: 358 | CI9: 358 | CJ9: 358 | CK9: 408 | CL9: 458 | CM9: 488 | CN9: 508 | CO9: 558 | CP9: 608 | CQ9: 608 | CR9: 608 | CS9: 608 | CT9: 608 | CU9: 608 | CV9: 608 | CW9: 645.6 | CX9: 745.6 | CY9: 858 | CZ9: 958 | DA9: 958
A10: 股份27%磷矿 | CZ10: 958 | DA10: 650
A11: 股份27%磷矿 | CZ11: 958 | DA11: 850
A12: 二铵/磷矿 | B12: =B8/B9 -> 5.5371063 | C12: =C8/C9 -> 5.8413201 | D12: =D8/D9 -> 6.216839 | E12: =E8/E9 -> 6.4832649 | F12: =F8/F9 -> 6.3714752 | G12: =G8/G9 -> 6.2894327 | H12: =H8/H9 -> 6.6239527 | I12: =I8/I9 -> 6.8692762 | ... CZ12: =CZ8/CZ9 -> 5.2967948
A13: 北方煤（兰花） | AX13: 964 | AY13: 984 | AZ13: 984 | BA13: 964 | BB13: 914 | BC13: 911 | BD13: 911 | BE13: 901 | BF13: 896 | BG13: 974 | BH13: 974 | BI13: 967 | BJ13: 917 | BK13: 917 | BL13: 903.67 | BM13: 886 | BN13: 876 | BO13: 866 | BP13: 839 | BQ13: 802.53 | BR13: 802.53 | BS13: 802.53 | BT13: 752.53 | BU13: 752.5 | BV13: 752.33 | BW13: 772.33 | BX13: 772.33 | BY13: 732.33 | BZ13: 702.33 | CA13: 755.67 | CB13: 755.67 | CC13: 692.66667 | CD13: 692.66667 | CE13: 769.33333 | CF13: 823 | CG13: 902.66667 | CH13: 1003 | CI13: 1003 | CJ13: 859 | CK13: 956 | CL13: 1125 | CM13: 1125 | CN13: 1203 | CO13: 1388 | CP13: 1588 | CQ13: 2309 | CR13: 1489 | CS13: 1416 | CT13: 1564.7616 | CU13: 1707.3545 | CV13: 1531.4466 | CW13: 1631.9322 | CX13: 1574.0976 | CY13: 1554.3867 | CZ13: 1491 | DA13: 1443
A30: =#REF! -> #REF!

Sheet 二铵、煤炭、硫磺、磷矿14年-22年
F1: 二铵 | J1: 原料+辅材+动力+维修+人工+包装
A2: 日期 | B2: 二铵 | C2: 尿素 | D2: 氯化铵 | E2: 二铵国际 | F2: 出口 | G2: 国内 | I2: 煤炭价格 | J2: 固定床尿素成本 | K2: 硫磺 | L2: 磷矿27%到厂 | M2: 尿素成本
A3: 14年1月 | B3: 2214.8425 | C3: 1588.9271 | D3: 515.52044 | E3: 405 | F3: 2234.4882 | G3: 2240.922 | I3: 827 | J3: =0.9*I3+50+1000+100+100+20 -> 2014.3 | K3: 1327 | L3: 400 | M3: =0.9*I3+50+1000 -> 1794.3
A4: 14年2月 | B4: 2336.528 | C4: 1492.504 | D4: 476.02094 | E4: 460.53571 | F4: 2450 | G4: 2346.6679 | I4: 800 | J4: =0.9*I4+50+1000+100+100+20 -> 1990 | K4: 1491 | L4: 400 | M4: =0.9*I4+50+1000 -> 1770
A5: 14年3月 | B5: 2486.7356 | C5: 1433.5488 | D5: 440.91951 | E5: 461.80645 | F5: 2543.228 | G5: 2415.5608 | I5: 770 | J5: =0.9*I5+50+1000+100+100+20 -> 1963 | K5: 1408 | L5: 400 | M5: =0.9*I5+50+1000 -> 1743
A6: 14年4月 | B6: 2463.6406 | C6: 1317.3171 | D6: 385.27182 | E6: 432.2 | F6: 2585.6642 | G6: 2475.4949 | I6: 735 | J6: =0.9*I6+50+1000+100+100+20 -> 1931.5 | K6: 1104 | L6: 380 | M6: =0.9*I6+50+1000 -> 1711.5
A7: 14年5月 | B7: 2421.1606 | C7: 1259.8514 | D7: 317.63403 | E7: 434.35484 | F7: 2420 | G7: 2429.4034 | I7: 695 | J7: =0.9*I7+50+1000+100+100+20 -> 1895.5 | K7: 1307 | L7: 380 | M7: =0.9*I7+50+1000 -> 1675.5
A8: 14年6月 | B8: 2389.9844 | C8: 1234.71 | D8: 289.51425 | E8: 436.6 | F8: 2507.9257 | G8: 2433.2804 | I8: 695 | J8: =0.9*I8+50+1000+100+100+20 -> 1895.5 | K8: 1315 | L8: 380 | M8: =0.9*I8+50+1000 -> 1675.5
A9: 14年7月 | B9: 2517.102 | C9: 1314.4808 | D9: 286.55565 | E9: 436.80645 | F9: 2516.4097 | G9: 2550 | I9: 671 | J9: =0.9*I9+50+1000+100+100+20 -> 1873.9 | K9: 1361 | L9: 380 | M9: =0.9*I9+50+1000 -> 1653.9
A10: 14年8月 | B10: 2610.325 | C10: 1298.9605 | D10: 283.39914 | E10: 455.32258 | F10: 2595.4545 | G10: 2650 | I10: 667 | J10: =0.9*I10+50+1000+100+100+20 -> 1870.3 | K10: 1291 | L10: 380 | M10: =0.9*I10+50+1000 -> 1650.3
A11: 14年9月 | B11: 2740.5815 | C11: 1326.4348 | D11: 286.92644 | E11: 472.93333 | F11: 2745 | G11: 2682.9476 | I11: 657 | J11: =0.9*I11+50+1000+100+100+20 -> 1861.3 | K11: 1197 | L11: 380 | M11: =0.9*I11+50+1000 -> 1641.3
A12: 14年10月 | B12: 2534.1563 | C12: 1374.4497 | D12: 286.63456 | E12: 475 | F12: 2515 | G12: 2552.7711 | I12: 657 | J12: =0.9*I12+50+1000+100+100+20 -> 1861.3 | K12: 1024 | L12: 380 | M12: =0.9*I12+50+1000 -> 1641.3
A13: 14年11月 | B13: 2670.6606 | C13: 1375.2627 | D13: 261.65254 | E13: 474.2 | F13: 2691.1766 | G13: 2556.4057 | I13: 677 | J13: =0.9*I13+50+1000+100+100+20 -> 1879.3 | K13: 1145 | L13: 380 | M13: =0.9*I13+50+1000 -> 1659.3
A14: 14年12月 | B14: 2577.8185 | C14: 1352.1107 | D14: 258.98965 | E14: 467 | F14: 2578.7581 | G14: 2577.0203 | I14: 677 | J14: =0.9*I14+50+1000+100+100+20 -> 1879.3 | K14: 1314 | L14: 380 | M14: =0.9*I14+50+1000 -> 1659.3
... A30: 16年4月 | B30: 2228.7594 | C30: 1135.4538 | D30: 437.63449 | E30: 331.36667 | F30: 2103.6083 | G30: 2340.2946 | I30: 509 | J30: =0.9*I30+50+1000+100+100+20 -> 1728.1 | K30: 767 | L30: 350 | M30: =0.9*I30+50+1000 -> 1508.1
A31: 16年5月 | B31: 2057.6541 | C31: 1049.3155 | D31: 456.06253 | E31: 332.67742 | F31: 2016.5554 | G31: 2202.0681 | I31: 529 | J31: =0.9*I31+50+1000+100+100+20 -> 1746.1 | K31: 753 | L31: 350 | M31: =0.9*I31+50+1000 -> 1526.1 | N31: 日期 | O31: 14年1月 | P31: 春节后价格与春节前对比 | Q31: 14年2月 | R31: 14年3月 | S31: 14年4月 | T31: 14年5月 | U31: 14年6月 | V31: 14年7月 | W31: 14年8月 | X31: 秋季市场价格与前两月对比 | Y31: 14年9月 | Z31: 14年10月 | AA31: 14年11月 | AB31: 14年12月
A32: 16年6月 | B32: 2037.7391 | C32: 1070.641 | D32: 411.52362 | E32: 330.73333 | F32: 2023.5383 | G32: 2129.528 | I32: 539 | J32: =0.9*I32+50+1000+100+100+20 -> 1755.1 | K32: 711 | L32: 350 | M32: =0.9*I32+50+1000 -> 1535.1 | N32: 二铵 | O32: 2214.8425 | P32: =AVERAGE(Q32:S32)/AVERAGE(O32)-1 -> 0.096677554 | Q32: 2336.528 | R32: 2486.7356 | S32: 2463.6406 | T32: 2421.1606 | U32: 2389.9844 | V32: 2517.102 | W32: 2610.325 | X32: =AVERAGE(Y32:Z32)/AVERAGE(V32:W32)-1 -> 0.028729957 | Y32: 2740.5815 | Z32: 2534.1563 | AA32: 2670.6606 | AB32: 2577.8185
A33: 16年7月 | B33: 2060.6494 | C33: 1022.4895 | D33: 411.72955 | E33: 329.80645 | F33: 2062.2232 | G33: 2050.0638 | I33: 539 | J33: =0.9*I33+50+1000+100+100+20 -> 1755.1 | K33: 669 | L33: 350 | M33: =0.9*I33+50+1000 -> 1535.1 | N33: 尿素 | O33: 1588.9271 | P33: =AVERAGE(Q33:S33)/AVERAGE(O33)-1 -> -0.10980392 | Q33: 1492.504 | R33: 1433.5488 | S33: 1317.3171 | T33: 1259.8514 | U33: 1234.71 | V33: 1314.4808 | W33: 1298.9605 | X33: =AVERAGE(Y33:Z33)/AVERAGE(V33:W33)-1 -> 0.033459052 | Y33: 1326.4348 | Z33: 1374.4497 | AA33: 1375.2627 | AB33: 1352.1107
A34: 16年8月 | B34: 2102.8897 | C34: 1036.9939 | D34: 395.94286 | E34: 327.16129 | F34: 2109.4381 | G34: 2035.7343 | I34: 519 | J34: =0.9*I34+50+1000+100+100+20 -> 1737.1 | K34: 689 | L34: 340 | M34: =0.9*I34+50+1000 -> 1517.1 | N34: 氯化铵 | O34: 515.52044 | P34: =AVERAGE(Q34:S34)/AVERAGE(O34)-1 -> -0.15799507 | Q34: 476.02094 | R34: 440.91951 | S34: 385.27182 | T34: 317.63403 | U34: 289.51425 | V34: 286.55565 | W34: 283.39914 | X34: =AVERAGE(Y34:Z34)/AVERAGE(V34:W34)-1 -> 0.0063271992 | Y34: 286.92644 | Z34: 286.63456 | AA34: 261.65254 | AB34: 258.98965
A35: 16年9月 | B35: 2033.4587 | C35: 905.98655 | D35: 373.5679 | E35: 320.4 | F35: 2032.0814 | G35: 2035.4372 | I35: 659 | J35: =0.9*I35+50+1000+100+100+20 -> 1863.1 | K35: 729 | L35: 340 | M35: =0.9*I35+50+1000 -> 1643.1 | O35: 15年1月 | Q35: 15年2月 | R35: 15年3月 | S35: 15年4月 | T35: 15年5月 | U35: 15年6月 | V35: 15年7月 | W35: 15年8月 | Y35: 15年9月 | Z35: 15年10月 | AA35: 15年11月 | AB35: 15年12月
A36: 16年10月 | B36: 1899.7562 | C36: 995.04361 | D36: 363.44388 | E36: 303.29032 | F36: 1882.3635 | G36: 2030.1856 | I36: 779 | J36: =0.9*I36+50+1000+100+100+20 -> 1971.1 | K36: 763 | L36: 340 | M36: =0.9*I36+50+1000 -> 1751.1 | N36: 二铵 | O36: 2589.444 | P36: =AVERAGE(Q36:S36)/AVERAGE(O36,AA32,AB32)-1 -> 0.022529576 | Q36: 2675.0397 | R36: 2661.9709 | S36: 2677.4974 | T36: 2720.9215 | U36: 2716.1916 | V36: 2717.9307 | W36: 2742.6795 | X36: =AVERAGE(Y36:Z36)/AVERAGE(V36:W36)-1 -> -0.011542884 | Y36: 2730.5512 | Z36: 2667.0278 | AA36: 2482.1079 | AB36: 2479.7249
A37: 16年11月 | B37: 1955.911 | C37: 1077.5492 | D37: 385.28286 | E37: 302.56667 | F37: 1909.2783 | G37: 2013.8131 | I37: 779 | J37: =0.9*I37+50+1000+100+100+20 -> 1971.1 | K37: 870 | L37: 340 | M37: =0.9*I37+50+1000 -> 1751.1 | N37: 尿素 | O37: 1398.4936 | P37: =AVERAGE(Q37:S37)/AVERAGE(O37,AA33,AB33)-1 -> 0.000216366 | Q37: 1377.9747 | R37: 1369.9045 | S37: 1378.8805 | T37: 1429.9393 | U37: 1551.24 | V37: 1542.0986 | W37: 1400.2932 | X37: =AVERAGE(Y37:Z37)/AVERAGE(V37:W37)-1 -> -0.14162818 | Y37: 1347.0938 | Z37: 1178.5725 | AA37: 1254.0078 | AB37: 1226.4003
A38: 16年12月 | B38: 1983.9083 | C38: 1166.9475 | D38: 452.10937 | E38: 314.87097 | F38: 1935.8515 | G38: 2031.6664 | I38: 799 | J38: =0.9*I38+50+1000+100+100+20 -> 1989.1 | K38: 897 | L38: 340 | M38: =0.9*I38+50+1000 -> 1769.1 | N38: 氯化铵 | O38: 255.21676 | P38: =AVERAGE(Q38:S38)/AVERAGE(O38,AA34,AB34)-1 -> 0.071804511 | Q38: 253.79593 | R38: 277.89929 | S38: 299.87391 | T38: 332.4167 | U38: 355.46348 | V38: 468.41953 | W38: 564.90534 | X38: =AVERAGE(Y38:Z38)/AVERAGE(V38:W38)-1 -> 0.019710943 | Y38: 585.74566 | Z38: 467.94702 | AA38: 396.97685 | AB38: 362.93739
A39: 17年1月 | B39: 2134.8937 | C39: 1312.6983 | D39: 517.87437 | E39: 343.3871 | F39: 2109.104 | G39: 2165.7681 | I39: 799 | J39: =0.9*I39+50+1000+100+100+20 -> 1989.1 | K39: 887 | L39: 340 | M39: =0.9*I39+50+1000 -> 1769.1 | O39: 16年1月 | Q39: 16年2月 | R39: 16年3月 | S39: 16年4月 | T39: 16年5月 | U39: 16年6月 | V39: 16年7月 | W39: 16年8月 | Y39: 16年9月 | Z39: 16年10月 | AA39: 16年11月 | AB39: 16年12月
A40: 17年2月 | B40: 2300.4024 | C40: 1353.2746 | D40: 532.70423 | E40: 362.28571 | F40: 2286.2948 | G40: 2305.2293 | I40: 799 | J40: =0.9*I40+50+1000+100+100+20 -> 1989.1 | K40: 907 | L40: 355 | M40: =0.9*I40+50+1000 -> 1769.1 | N40: 二铵 | O40: 2369.1368 | P40: =AVERAGE(Q40:S40)/AVERAGE(O40,AA36,AB36)-1 -> -0.048899631 | Q40: 2389.9206 | R40: 2353.8078 | S40: 2228.7594 | T40: 2057.6541 | U40: 2037.7391 | V40: 2060.6494 | W40: 2102.8897 | X40: =AVERAGE(Y40:Z40)/AVERAGE(V40:W40)-1 -> -0.055319361 | Y40: 2033.4587 | Z40: 1899.7562 | AA40: 1955.911 | AB40: 1983.9083
A41: 17年3月 | B41: 2353.5189 | C41: 1312.426 | D41: 470.46185 | E41: 367.48387 | F41: 2354.021 | G41: 2353.0414 | I41: 799 | J41: =0.9*I41+50+1000+100+100+20 -> 1989.1 | K41: 893 | L41: 355 | M41: =0.9*I41+50+1000 -> 1769.1 | N41: 尿素 | O41: 1152.0803 | P41: =AVERAGE(Q41:S41)/AVERAGE(O41,AA37,AB37)-1 -> -0.078792802 | Q41: 1099.7143 | R41: 1111.1063 | S41: 1135.4538 | T41: 1049.3155 | U41: 1070.641 | V41: 1022.4895 | W41: 1036.9939 | X41: =AVERAGE(Y41:Z41)/AVERAGE(V41:W41)-1 -> -0.076938325 | Y41: 905.98655 | Z41: 995.04361 | AA41: 1077.5492 | AB41: 1166.9475
A42: 17年4月 | B42: 2376.9914 | C42: 1330.1959 | D42: 399.80999 | E42: 359.23333 | F42: 2378.8964 | G42: 2374.0874 | I42: 836 | J42: =0.9*I42+50+1000+100+100+20 -> 2022.4 | K42: 803 | L42: 355 | M42: =0.9*I42+50+1000 -> 1802.4 | N42: 氯化铵 | O42: 352.1785 | P42: =AVERAGE(Q42:S42)/AVERAGE(O42,AA38,AB38)-1 -> 0.028853909 | Q42: 341.43891 | R42: 365.10758 | S42: 437.63449 | T42: 456.06253 | U42: 411.52362 | V42: 411.72955 | W42: 395.94286 | X42: =AVERAGE(Y42:Z42)/AVERAGE(V42:W42)-1 -> -0.087486726 | Y42: 373.5679 | Z42: 363.44388 | AA42: 385.28286 | AB42: 452.10937
A43: 17年5月 | B43: 2370.111 | C43: 1256.7046 | D43: 381.1962 | E43: 350.54839 | F43: 2376.0101 | G43: 2321.9835 | I43: 836 | J43: =0.9*I43+50+1000+100+100+20 -> 2022.4 | K43: 813 | L43: 355 | M43: =0.9*I43+50+1000 -> 1802.4 | O43: 17年1月 | Q43: 17年2月 | R43: 17年3月 | S43: 17年4月 | T43: 17年5月 | U43: 17年6月 | V43: 17年7月 | W43: 17年8月 | Y43: 17年9月 | Z43: 17年10月 | AA43: 17年11月 | AB43: 17年12月
A44: 17年6月 | B44: 2285.1173 | C44: 1342.4411 | D44: 373.94564 | E44: 341.43333 | F44: 2281.1174 | G44: 2322.5919 | I44: 811 | J44: =0.9*I44+50+1000+100+100+20 -> 1999.9 | K44: 837 | L44: 355 | M44: =0.9*I44+50+1000 -> 1779.9 | N44: 二铵 | O44: 2134.8937 | P44: =AVERAGE(Q44:S44)/AVERAGE(O44,AA40,AB40)-1 -> 0.15740656 | Q44: 2300.4024 | R44: 2353.5189 | S44: 2376.9914 | T44: 2370.111 | U44: 2285.1173 | V44: 2235.389 | W44: 2225.4675 | X44: =AVERAGE(Y44:Z44)/AVERAGE(V44:W44)-1 -> 0.0010705388 | Y44: 2229.8995 | Z44: 2235.7325 | AA44: 2329.2131 | AB44: 2470.3062
A45: 17年7月 | B45: 2235.389 | C45: 1379.4437 | D45: 374.24002 | E45: 338.1129 | F45: 2221.0173 | G45: 2292.5487 | I45: 824 | J45: =0.9*I45+50+1000+100+100+20 -> 2011.6 | K45: 902 | L45: 355 | M45: =0.9*I45+50+1000 -> 1791.6 | N45: 尿素 | O45: 1312.6983 | P45: =AVERAGE(Q45:S45)/AVERAGE(O45,AA41,AB41)-1 -> 0.12332794 | Q45: 1353.2746 | R45: 1312.426 | S45: 1330.1959 | T45: 1256.7046 | U45: 1342.4411 | V45: 1379.4437 | W45: 1230.3258 | X45: =AVERAGE(Y45:Z45)/AVERAGE(V45:W45)-1 -> 0.054429048 | Y45: 1289.3319 | Z45: 1462.4848 | AA45: 1547.5496 | AB45: 1573.9015
A46: 17年8月 | B46: 2225.4675 | C46: 1230.3258 | D46: 379.41374 | E46: 339.54839 | F46: 2206.4127 | G46: 2298.0614 | I46: 914 | J46: =0.9*I46+50+1000+100+100+20 -> 2092.6 | K46: 983 | L46: 355 | M46: =0.9*I46+50+1000 -> 1872.6 | N46: 氯化铵 | O46: 517.87437 | P46: =AVERAGE(Q46:S46)/AVERAGE(O46,AA42,AB42)-1 -> 0.035203015 | Q46: 532.70423 | R46: 470.46185 | S46: 399.80999 | T46: 381.1962 | U46: 373.94564 | V46: 374.24002 | W46: 379.41374 | X46: =AVERAGE(Y46:Z46)/AVERAGE(V46:W46)-1 -> 0.022191049 | Y46: 380.59659 | Z46: 389.78153 | AA46: 420.03638 | AB46: 456.30645
A47: 17年9月 | B47: 2229.8995 | C47: 1289.3319 | D47: 380.59659 | E47: 350.5 | F47: 2214.5449 | G47: 2299.4437 | I47: 1024 | J47: =0.9*I47+50+1000+100+100+20 -> 2191.6 | K47: 1045 | L47: 355 | M47: =0.9*I47+50+1000 -> 1971.6 | O47: 18年1月 | Q47: 18年2月 | R47: 18年3月 | S47: 18年4月 | T47: 18年5月 | U47: 18年6月 | V47: 18年7月 | W47: 18年8月 | Y47: 18年9月 | Z47: 18年10月 | AA47: 18年11月 | AB47: 18年12月
A48: 17年10月 | B48: 2235.7325 | C48: 1462.4848 | D48: 389.78153 | E48: 360.85484 | F48: 2213.2155 | G48: 2301.1431 | I48: 1024 | J48: =0.9*I48+50+1000+100+100+20 -> 2191.6 | K48: 1386 | L48: 355 | M48: =0.9*I48+50+1000 -> 1971.6 | N48: 二铵 | O48: 2501.2773 | P48: =AVERAGE(Q48:S48)/AVERAGE(O48,AA44,AB44)-1 -> 0.05090294 | Q48: 2526.6649 | R48: 2597.1353 | S48: 2548.6285 | T48: 2565.6194 | U48: 2575.9278 | V48: 2678.8684 | W48: 2733.1973 | X48: =AVERAGE(Y48:Z48)/AVERAGE(V48:W48)-1 -> 0.01401138 | Y48: 2745.262 | Z48: 2742.6343 | AA48: 2700 | AB48: 2700
A49: 17年11月 | B49: 2329.2131 | C49: 1547.5496 | D49: 420.03638 | E49: 383.78333 | F49: 2250.8343 | G49: 2388.5134 | I49: 974 | J49: =0.9*I49+50+1000+100+100+20 -> 2146.6 | K49: 1602 | L49: 355 | M49: =0.9*I49+50+1000 -> 1926.6 | N49: 尿素 | O49: 1635.4016 | P49: =AVERAGE(Q49:S49)/AVERAGE(O49,AA45,AB45)-1 -> 0.056250467 | Q49: 1708.028 | R49: 1685.1699 | S49: 1631.23 | T49: 1720.0567 | U49: 1803.3435 | V49: 1648.6336 | W49: 1640.7106 | X49: =AVERAGE(Y49:Z49)/AVERAGE(V49:W49)-1 -> 0.11411778 | Y49: 1756.998 | Z49: 1907.7189 | AA49: 1970 | AB49: 1900
A50: 17年12月 | B50: 2470.3062 | C50: 1573.9015 | D50: 456.30645 | E50: 405.80645 | F50: 2485.3958 | G50: 2463.9583 | I50: 944 | J50: =0.9*I50+50+1000+100+100+20 -> 2119.6 | K50: 1301 | L50: 430 | M50: =0.9*I50+50+1000 -> 1899.6 | N50: 氯化铵 | O50: 485.44029 | P50: =AVERAGE(Q50:S50)/AVERAGE(O50,AA46,AB46)-1 -> 0.13442429 | Q50: 550.90466 | R50: 522.53553 | S50: 471.39966 | T50: 481.766 | U50: 493.81541 | V50: 543.96639 | W50: 547.83487 | X50: =AVERAGE(Y50:Z50)/AVERAGE(V50:W50)-1 -> 0.16872371 | Y50: 616.46036 | Z50: 659.55365 | AA50: 712.53991 | AB50: 719.29174
A51: 18年1月 | B51: 2501.2773 | C51: 1635.4016 | D51: 485.44029 | E51: 408.54839 | F51: 2532.6354 | G51: 2482.6749 | I51: 964 | J51: =0.9*I51+50+1000+100+100+20 -> 2137.6 | K51: 1184 | L51: 430 | M51: =0.9*I51+50+1000 -> 1917.6 | O51: 19年1月 | Q51: 19年2月 | R51: 19年3月 | S51: 19年4月 | T51: 19年5月 | U51: 19年6月 | V51: 19年7月 | W51: 19年8月 | Y51: 19年9月 | Z51: 19年10月 | AA51: 19年11月 | AB51: 19年12月
A52: 18年2月 | B52: 2526.6649 | C52: 1708.028 | D52: 550.90466 | E52: 411.78571 | F52: 2483.3838 | G52: 2558.6549 | I52: 984 | J52: =0.9*I52+50+1000+100+100+20 -> 2155.6 | K52: 1199 | L52: 430 | M52: =0.9*I52+50+1000 -> 1935.6 | N52: 二铵 | O52: 2614 | P52: =AVERAGE(Q52:S52)/AVERAGE(O52,AA48,AB48)-1 -> -0.044481843 | Q52: 2625 | R52: 2520.3918 | S52: 2512.1307 | T52: 2429.0092 | U52: 2407.3258 | V52: 2214.2749 | W52: 2214.1737 | X52: =AVERAGE(Y52:Z52)/AVERAGE(V52:W52)-1 -> -0.023078981 | Y52: 2187.0372 | Z52: 2139.2073 | AA52: 2103.8387 | AB52: 2061.2315
A53: 18年3月 | B53: 2597.1353 | C53: 1685.1699 | D53: 522.53553 | E53: 413.79032 | F53: 2608.7903 | G53: 2591.9831 | I53: 984 | J53: =0.9*I53+50+1000+100+100+20 -> 2155.6 | K53: 1117 | L53: 430 | M53: =0.9*I53+50+1000 -> 1935.6 | N53: 尿素 | O53: 1700 | P53: =AVERAGE(Q53:S53)/AVERAGE(O53,AA49,AB49)-1 -> -0.059128645 | Q53: 1650 | R53: 1739.2984 | S53: 1851.3551 | T53: 1737.2891 | U53: 1693.2258 | V53: 1645.6369 | W53: 1578.8262 | X53: =AVERAGE(Y53:Z53)/AVERAGE(V53:W53)-1 -> -0.045984399 | Y53: 1551.4086 | Z53: 1524.7795 | AA53: 1496.5959 | AB53: 1483.6688
A54: 18年4月 | B54: 2548.6285 | C54: 1631.23 | D54: 471.39966 | E54: 409.91667 | F54: 2543.0642 | G54: 2577.5277 | I54: 964 | J54: =0.9*I54+50+1000+100+100+20 -> 2137.6 | K54: 1059 | L54: 430 | M54: =0.9*I54+50+1000 -> 1917.6 | N54: 氯化铵 | O54: 663.24197 | P54: =AVERAGE(Q54:S54)/AVERAGE(O54,AA50,AB50)-1 -> -0.10727306 | Q54: 633.32865 | R54: 584 | S54: 653 | T54: 698 | U54: 655 | V54: 664 | W54: 650 | X54: =AVERAGE(Y54:Z54)/AVERAGE(V54:W54)-1 -> -0.15905632 | Y54: 570 | Z54: 535 | AA54: 474 | AB54: 439.41767
A55: 18年5月 | B55: 2565.6194 | C55: 1720.0567 | D55: 481.766 | E55: 412.6129 | F55: 2566.0679 | G55: 2557.9926 | I55: 914 | J55: =0.9*I55+50+1000+100+100+20 -> 2092.6 | K55: 1127 | L55: 430 | M55: =0.9*I55+50+1000 -> 1872.6
...

Sheet 走势图
A1: 日期 | B1: 14年1月 | C1: 14年2月 | D1: 14年3月 | E1: 14年4月 | F1: 14年5月 | G1: 14年6月 | H1: 14年7月 | I1: 14年8月 | J1: 14年9月 | K1: 14年10月 | L1: 14年11月 | M1: 14年12月 | N1: 15年1月 | O1: 15年2月 | P1: 15年3月 | Q1: 15年4月 | R1: 15年5月 | S1: 15年6月 | T1: 15年7月 | U1: 15年8月 | V1: 15年9月 | W1: 15年10月 | X1: 15年11月 | Y1: 15年12月 | Z1: 16年1月 | AA1: 16年2月 | AB1: 16年3月 | AC1: 16年4月 | AD1: 16年5月 | AE1: 16年6月 | AF1: 16年7月 | AG1: 16年8月 | AH1: 16年9月 | AI1: 16年10月 | AJ1: 16年11月 | AK1: 16年12月 | AL1: 17年1月 | AM1: 17年2月 | AN1: 17年3月 | AO1: 17年4月 | AP1: 17年5月 | AQ1: 17年6月 | AR1: 17年7月 | AS1: 17年8月 | AT1: 17年9月 | AU1: 17年10月 | AV1: 17年11月 | AW1: 17年12月 | AX1: 18年1月 | AY1: 18年2月 | AZ1: 18年3月 | BA1: 18年4月 | BB1: 18年5月 | BC1: 18年6月 | BD1: 18年7月 | BE1: 18年8月 | BF1: 18年9月 | BG1: 18年10月 | BH1: 18年11月 | BI1: 18年12月 | BJ1: 19年1月 | BK1: 19年2月 | BL1: 19年3月 | BM1: 19年4月 | BN1: 19年5月 | BO1: 19年6月 | BP1: 19年7月 | BQ1: 19年8月 | BR1: 19年9月 | BS1: 19年10月 | BT1: 19年11月 | BU1: 19年12月 | BV1: 20年1月 | BW1: 20年2月 | BX1: 20年3月 | BY1: 20年4月 | BZ1: 20年5月 | CA1: 20年6月 | CB1: 20年7月 | CC1: 20年8月 | CD1: 20年9月 | CE1: 20年10月 | CF1: 20年11月 | CG1: 20年12月 | CH1: 21年1月 | CI1: 21年2月 | CJ1: 21年3月 | CK1: 21年4月 | CL1: 21年5月 | CM1: 21年6月 | CN1: 21年7月 | CO1: 21年8月 | CP1: 21年9月 | CQ1: 21年10月 | CR1: 21年11月 | CS1: 21年12月 | CT1: 22年1月 | CU1: 22年2月 | CV1: 22年3月 | CW1: 22年4月 | CX1: 22年5月 | CY1: 22年6月 | CZ1: 22年7月 | DF1: 价格预测 | DL1: 下半年价格
A2: 二铵 | B2: 2214.8425 | C2: 2336.528 | D2: 2486.7356 | E2: 2463.6406 | F2: 2421.1606 | G2: 2389.9844 | H2: 2517.102 | I2: 2610.325 | J2: 2740.5815 | K2: 2534.1563 | L2: 2670.6606 | M2: 2577.8185 | N2: 2589.444 | O2: 2675.0397 | P2: 2661.9709 | Q2: 2677.4974 | R2: 2720.9215 | S2: 2716.1916 | T2: 2717.9307 | U2: 2742.6795 | V2: 2730.5512 | W2: 2667.0278 | X2: 2482.1079 | Y2: 2479.7249 | Z2: 2369.1368 | AA2: 2389.9206 | AB2: 2353.8078 | AC2: 2228.7594 | AD2: 2057.6541 | AE2: 2037.7391 | AF2: 2060.6494 | AG2: 2102.8897 | AH2: 2033.4587 | AI2: 1899.7562 | AJ2: 1955.911 | AK2: 1983.9083 | AL2: 2134.8937 | AM2: 2300.4024 | AN2: 2353.5189 | AO2: 2376.9914 | AP2: 2370.111 | AQ2: 2285.1173 | AR2: 2235.389 | AS2: 2225.4675 | AT2: 2229.8995 | AU2: 2235.7325 | AV2: 2329.2131 | AW2: 2470.3062 | AX2: 2501.2773 | AY2: 2526.6649 | AZ2: 2597.1353 | BA2: 2548.6285 | BB2: 2565.6194 | BC2: 2575.9278 | BD2: 2678.8684 | BE2: 2733.1973 | BF2: 2745.262 | BG2: 2742.6343 | BH2: 2700 | BI2: 2700 | BJ2: 2614 | BK2: 2625 | BL2: 2520.3918 | BM2: 2512.1307 | BN2: 2429.0092 | BO2: 2407.3258 | BP2: 2214.2749 | BQ2: 2214.1737 | BR2: 2187.0372 | BS2: 2139.2073 | BT2: 2103.8387 | BU2: 2061.2315 | BV2: 2085.8565 | BW2: 1986.9905 | BX2: 1986.9905 | BY2: 2071.5497 | BZ2: 2060.8699 | CA2: 2071.9194 | CB2: 2098.8153 | CC2: 2082.682 | CD2: 2176.0454 | CE2: 2238.3727 | CF2: 2273.7149 | CG2: 2310.9231 | CH2: 2365.1228 | CI2: 2471.1848 | CJ2: 2727.3676 | CK2: 3293.7439 | CL2: 3225.7658 | CM2: 3262.175 | CN2: 3373.0201 | CO2: 3508.2873 | CP2: 3780.2887 | CQ2: 3742.6374 | CR2: 3536.1539 | CS2: 3536.0994 | CT2: 3635.9425 | CU2: 3566.1321 | CV2: 4271.2606 | CW2: 4362 | CX2: 5029 | CY2: 5280 | CZ2: 5074.3294 | DL2: =(5900*22+4000*63)/85 -> 4491.7647 | DM2: =(5900*22+4000*63)/85 -> 4491.7647 | DN2: =(5900*22+4000*63)/85 -> 4491.7647 | DO2: =AVERAGE(B2:CZ2) -> 2621.1003 | DP2: =MAX(B2:CZ2) -> 5280 | DQ2: =MIN(B2:CZ2) -> 1899.7562
A3: 二铵 | CZ3: 5074.3294 | DA3: 4400 | DB3: 4400 | DC3: 4400 | DD3: 4400 | DE3: 4400 | DF3: 4400 | DG3: 4400 | DH3: 4400 | DI3: 4400 | DJ3: 4400 | DK3: 4400
